Workbook
Name __DemandLoad: TRUE
Name \a: #REF!
Name \a: #REF!
Name \a: #REF!
Name \a: #REF!
Name \a: #REF!
Name \a: #REF!
Name \b: #REF!
Name \b: #REF!
Name \b: #REF!
Name \b: #REF!
Name \b: #REF!
Name \b: #REF!
Name \c: #REF!
Name \c: #REF!
Name \c: #REF!
Name \c: #REF!
Name \c: #REF!
Name \c: #REF!
Name \d: #REF!
Name \d: #REF!
Name \d: #REF!
Name \d: #REF!
Name \d: #REF!
Name \d: #REF!
Name \e: #REF!
Name \e: #REF!
Name \e: #REF!
Name \e: #REF!
Name \e: #REF!
Name \e: #REF!
Name \f: #REF!
Name \f: #REF!
Name \f: #REF!
Name \f: #REF!
Name \f: #REF!
Name \f: #REF!
Name \g: #REF!
Name \g: #REF!
Name \g: #REF!
Name \g: #REF!
Name \g: #REF!
Name \g: #REF!
Name \h: #REF!
Name \h: #REF!
Name \h: #REF!
Name \h: #REF!
Name \h: #REF!
Name \h: #REF!
Name \i: #REF!
Name \i: #REF!
Name \i: #REF!
Name \i: #REF!
Name \i: #REF!
Name \i: #REF!
Name \j: #REF!
Name \j: #REF!
Name \j: #REF!
Name \j: #REF!
Name \j: #REF!

Sheet 정리표 (마루높이)
A1: 기존시설(50년)
A2: 구분 | B2: B | C2: C | D2: D
B3: 산정 마루높이 | C3: 산정 마루높이 | D3: 산정 마루높이
A4: 항만 및 어항 설계기준 | B4: DL(+)5.46~7.73m | C4: DL(+)5.88~8.61m | D4: DL(+)5.76~8.36m
A5: 처오름높이 | B5: ='나.마루높이검토(기존시설50년)'!O14 -> 8.081 | C5: ='나.마루높이검토(기존시설50년)'!W14 -> 9.026 | D5: ='나.마루높이검토(기존시설50년)'!AD14 -> 8.756
A6: 허용월파량 | B6: ='나.마루높이검토(기존시설50년)'!O15 -> #REF! | C6: ='나.마루높이검토(기존시설50년)'!W15 -> #REF! | D6: ='나.마루높이검토(기존시설50년)'!AD15 -> #REF!
A7: 전달파고 | B7: ='나.마루높이검토(기존시설50년)'!O16 -> 6 | C7: ='나.마루높이검토(기존시설50년)'!W16 -> 6.6 | D7: ='나.마루높이검토(기존시설50년)'!AD16 -> 6.4
A9: 기존시설(100년)
A10: 구분 | B10: B | C10: C | D10: D
B11: 산정 마루높이 | C11: 산정 마루높이 | D11: 산정 마루높이
A12: 항만 및 어항 설계기준 | B12: DL(+)5.52~7.86m | C12: DL(+)5.94~8.73m | D12: DL(+)5.88~8.61m
A13: 처오름높이 | B13: ='2.2 기존시설 마루높이'!K14 -> 8.216 | C13: ='2.2 기존시설 마루높이'!T14 -> 9.161 | D13: ='2.2 기존시설 마루높이'!AC14 -> 9.026
A14: 허용월파량 | B14: ='2.2 기존시설 마루높이'!K15 -> 8.0972008 | C14: ='2.2 기존시설 마루높이'!T15 -> 9.6036151 | D14: ='2.2 기존시설 마루높이'!AC15 -> 9.5910321
A15: 전달파고 | B15: ='2.2 기존시설 마루높이'!K16 -> 6.1 | C15: ='2.2 기존시설 마루높이'!T16 -> 6.7 | D15: ='2.2 기존시설 마루높이'!AC16 -> 6.6
A17: 신규시설(50년)
A18: 구분 | B18: A | C18: E
B19: 산정 마루높이 | C19: 산정 마루높이
A20: 항만 및 어항 설계기준 | B20: DL(+)5.64~8.11m | C20: DL(+)6.00~8.86m
A21: 처오름높이 | B21: ='3.1.1 마루높이 결정(2)'!AY13 -> 0 | C21: ='3.1.1 마루높이 결정(2)'!AY20 -> 0
A22: 허용월파량 | B22: ='3.1.1 마루높이 결정(2)'!#REF! -> #REF! | C22: ='3.1.1 마루높이 결정(2)'!#REF! -> #REF!
A23: 전달파고 | B23: ='3.1.1 마루높이 결정(2)'!AY14 -> 0 | C23: ='3.1.1 마루높이 결정(2)'!AY21 -> 0
A25: 신규시설(100년)
A26: 구분 | B26: A | C26: E
B27: 산정 마루높이 | C27: 산정 마루높이
A28: 항만 및 어항 설계기준 | B28: DL(+)5.76~8.36m | C28: DL(+)6.18~9.23m
A29: 처오름높이 | B29: ='3.1.1 마루높이 결정(2)'!O13 -> 9.255 | C29: ='3.1.1 마루높이 결정(2)'!BJ20 -> 0
A30: 허용월파량 | B30: ='3.1.1 마루높이 결정(2)'!AB13 -> 0 | C30: ='3.1.1 마루높이 결정(2)'!#REF! -> #REF!
A31: 전달파고 | B31: ='3.1.1 마루높이 결정(2)'!O14 -> 6 | C31: ='3.1.1 마루높이 결정(2)'!BJ21 -> 0

Sheet 정리표 (피복석)
A1: 기존시설(50년)
A2: 구분 | B2: B | D2: C | F2: D
B3: 산정 소요질량 | C3: 적용 T.T.P | D3: 산정 소요질량 | E3: 적용 T.T.P | F3: 산정 소요질량 | G3: 적용 T.T.P
A4: 허드슨 | B4: 4.37 | C4: ='1.1.3 피복재 (기존시설50년)'!L20 -> 5 | D4: 7.56 | E4: ='1.1.3 피복재 (기존시설50년)'!Q20 -> 10 | F4: 6.53 | G4: ='1.1.3 피복재 (기존시설50년)'!V20 -> 8
A5: 반데미어 | B5: 6.09 | C5: ='1.1.3 피복재 (기존시설50년)'!L21 -> 8 | D5: 11.28 | E5: ='1.1.3 피복재 (기존시설50년)'!Q21 -> 16 | F5: 9.64 | G5: ='1.1.3 피복재 (기존시설50년)'!V21 -> 12.5
A6: 다까하시 | B6: 5.61 | C6: ='1.1.3 피복재 (기존시설50년)'!L22 -> 6.3 | D6: 9.69 | E6: ='1.1.3 피복재 (기존시설50년)'!Q22 -> 12.5 | F6: 7.64 | G6: ='1.1.3 피복재 (기존시설50년)'!V22 -> 10
A8: 기존시설(100년)
A9: 구분 | B9: B | D9: C | F9: D
B10: 산정 소요질량 | C10: 적용 T.T.P | D10: 산정 소요질량 | E10: 적용 T.T.P | F10: 산정 소요질량 | G10: 적용 T.T.P
A11: 허드슨 | B11: ='2.4 기존시설 피복재검토'!AM61 -> 4.7589223 | C11: 6.3 | D11: ='2.4 기존시설 피복재검토'!AM64 -> 8.1097315 | E11: 10 | F11: ='2.4 기존시설 피복재검토'!AM67 -> 7.5569923 | G11: 10
A12: 반데미어 | B12: ='2.4 기존시설 피복재검토'!AM97 -> 6.2454747 | C12: 8 | D12: ='2.4 기존시설 피복재검토'!AM106 -> 12.160949 | E12: 16 | F12: ='2.4 기존시설 피복재검토'!AM115 -> 11.133874 | G12: 12.5
A13: 다까하시 | B13: ='2.4 기존시설 피복재검토'!AM157 -> 6.1049161 | C13: 8 | D13: ='2.4 기존시설 피복재검토'!AM164 -> 10.403454 | E13: 12.5 | F13: ='2.4 기존시설 피복재검토'!AM171 -> 8.8466251 | G13: 10
A15: 신규시설(50년)
A16: 구분 | B16: A | D16: E
B17: 산정 소요질량 | C17: 적용 T.T.P | D17: 산정 소요질량 | E17: 적용 T.T.P
A18: 허드슨 | B18: ='3.1.3 피복재 소요중량'!#REF! -> #REF! | C18: 6.3 | D18: ='3.1.3 피복재 소요중량'!#REF! -> #REF! | E18: 10
A19: 반데미어 | B19: ='3.1.3 피복재 소요중량'!#REF! -> #REF! | C19: 10 | D19: ='3.1.3 피복재 소요중량'!#REF! -> #REF! | E19: 16
A20: 다까하시 | B20: ='3.1.3 피복재 소요중량'!#REF! -> #REF! | C20: 8 | D20: ='3.1.3 피복재 소요중량'!#REF! -> #REF! | E20: 12.5
A22: 신규시설(100년)
A23: 구분 | B23: A | D23: E
B24: 산정 소요질량 | C24: 적용 T.T.P | D24: 산정 소요질량 | E24: 적용 T.T.P
A25: 허드슨 | B25: ='3.1.3 피복재 소요중량'!AM56 -> 6.5271461 | C25: 8 | D25: ='3.1.3 피복재 소요중량'!AM59 -> 10.588561 | E25: 12.5
A26: 반데미어 | B26: ='3.1.3 피복재 소요중량'!AM90 -> 9.3921491 | C26: 12.5 | D26: ='3.1.3 피복재 소요중량'!AM98 -> 16.976377 | E26: 20
A27: 다까하시 | B27: ='3.1.3 피복재 소요중량'!AM140 -> 8.3732571 | C27: 10 | D27: ='3.1.3 피복재 소요중량'!AM148 -> 12.395544 | E27: 16

Sheet 3.1.1 마루높이 결정(1)
A1: 추자항 파제제 축조공사
A2: 3.1 주요제원검토
A3: 3.1.1 마루높이 결정
A4: 가. 마루높이 결정
A5: 1) 검토방향
B6: ▸ 마루높이는 일반적으로 배후수역의 정온도, 배후 항만시설의 보전등을 감안
B7: 설계조위상 적정한 마루높이로 결정
A9: 2) 검토방법
B10: ▸ 마루높이는 다음의 방법을 고려하여 결정
B11: - 항만 및 어항설계기준에 의한 방법
B12: - 처오름높이에 의한 방법
B13: - 항내 전달파고에 의한 방법
B14: - 인근 구조물 마루높이 조사
A16: 3) 검토조건
B17: 가) 파랑조건
B18: 구 분 | L18: 파고(H⅓) | Q18: 주기(T⅓) | W18: 설계수심 | AC18: 해저경사 | AI18: 비 고
B19: 북측파제제 | L19: 4 | Q19: 11.5 | W19: -5.1 | AC19: 0.02
B20: 남측파제제 | L20: 4.7 | Q20: 11.6 | W20: -10.5 | AC20: 0.02
B22: 나) 조위조건
B23: 구 분 | P23: 조 위 (m) | W23: 조 위 표
B24: 약최고고조위 | I24: Aprox.H.H.W | P24: 3.356
B25: 대조평균고조위 | I25: H.W.O.S.T | P25: 2.904
B26: 평균고조위 | I26: H.W.O.M.T | P26: 2.554
B27: 소조평균고조위 | I27: H.W.O.N.T | P27: 2.204
B28: 평균해면 | I28: M.S.L | P28: 1.678
B29: 소조평균저조위 | I29: L.W.O.N.T | P29: 1.152
B30: 평균저조위 | I30: L.W.O.M.T | P30: 0.802
B31: 대조평균저조위 | I31: L.W.O.S.T | P31: 0.452
B32: 약최저저조위 | I32: Aprox.L.L.W | P32: 0
B33: 다) 해수면상승고
B34: ▸ IPCC에서 발행한 SSP 1-2.6 시나리오(2015~2100)에 기반하여 해수면상승을 고려
B35: - 시나리오 결과 광역 해수면 상승고 및 상승률은 다음 그림과 같음
B36: <해수면 상승폭> (2015년~2100년) | V36: <해수면 상승률>
B47: - 추자도 해수면 상승고 및 상승률은 다음 그림과 같음
B48: <해수면 상승폭> (2015년~2100년) | R48: 단위 : cm | U48: <해수면 상승률> | AL48: 단위 : mm / 년
B59: 구 분 | G59: 해수면상승률(m/year) | Q59: 재현빈도 | Z59: 해수면상승고(m) | AI59: 비 고
B60: 추자도 지역 | G60: 0.00499 | Q60: 100 | Z60: =G60*Q60 -> 0.499
B62: 라) 설계조위
B63: - 설계조위는 약최고고조위에 해수면상승고를 고려한 | S63: =P24+Z60 -> 3.855 | Y63: 로 결정

Sheet 4) 설계고조위
A1: 4) 설계 고조위
B2: 구 분 | K2: 산 정 방 법 | AE2: 비 고
B3: 제1방법 | K3: 기왕의 고극조위 | AE3: 30년간 관측자료
B4: 제2방법 | K4: 약최고고조위 + 조위편차 | AE4: 30년간 관측자료
B5: 제3방법 | K5: 약최고고조위 + 폭풍해일고 | AE5: 30년간 관측자료
B6: 주) 항만 및 어항 설계기준(KDS 64 10 10 : 2017, p186, 해양수산부) 참조
B8: - 약최고고조위(APP. H.H.W) | P8: ='3.1.1 마루높이 결정(1)'!P24:V24 -> 3.356
B9: - 약최고고조위(APP. H.H.W)(부산) | P9: ='3.1.1 마루높이 결정(1)'!P24:V24 -> 3.356
B11: 가) 기왕의 고극조위(Obs. H.H.W) : | P11: =MAX((H14:N23),(U14:AA23),(AH14:AN23)) -> 2.11
B12: - 부산항의 고극조위 관측기록치를 이용하여 고극조위 산정 | AK12: (단위 :m)
B13: 년 도 | H13: 고극조위 | O13: 년 도 | U13: 고극조위 | AB13: 년 도 | AH13: 고극조위
B14: 1992 | H14: 1.61 | O14: 2002 | U14: 1.65 | AB14: 2012 | AH14: 1.84
B15: =B14+1 -> 1993 | H15: 1.51 | O15: =O14+1 -> 2003 | U15: 2.11 | AB15: =AB14+1 -> 2013 | AH15: 1.56
B16: =B15+1 -> 1994 | H16: 1.55 | O16: =O15+1 -> 2004 | U16: 1.69 | AB16: =AB15+1 -> 2014 | AH16: 1.7
B17: =B16+1 -> 1995 | H17: 1.49 | O17: =O16+1 -> 2005 | U17: 1.68 | AB17: =AB16+1 -> 2015 | AH17: 1.62
B18: =B17+1 -> 1996 | H18: 1.58 | O18: =O17+1 -> 2006 | U18: 1.62 | AB18: =AB17+1 -> 2016 | AH18: 1.74
B19: =B18+1 -> 1997 | H19: 1.58 | O19: =O18+1 -> 2007 | U19: 1.57 | AB19: =AB18+1 -> 2017 | AH19: 1.62
B20: =B19+1 -> 1998 | H20: 1.6 | O20: =O19+1 -> 2008 | U20: 1.56 | AB20: =AB19+1 -> 2018 | AH20: 1.69
B21: =B20+1 -> 1999 | H21: 1.65 | O21: =O20+1 -> 2009 | U21: 1.57 | AB21: =AB20+1 -> 2019 | AH21: 1.65
B22: =B21+1 -> 2000 | H22: 1.68 | O22: =O21+1 -> 2010 | U22: 1.71 | AB22: =AB21+1 -> 2020 | AH22: 1.84
B23: =B22+1 -> 2001 | H23: 1.69 | O23: =O22+1 -> 2011 | U23: 1.52 | AB23: =AB22+1 -> 2021 | AH23: 1.71
B25: 나) 약최고고조위(App. H.H.W)에 기왕최대조위편차를 더한 조위
B26: - 약최고고조위(App. H.H.W) + 조위편차 = | T26: =P9 -> 3.356 | X26: + | Y26: =MAX((H28:N37),(U28:AA37),(AH28:AN37))/100 -> 0.0036 | AB26: = | AC26: =T26+Y26 -> 3.3596 | AK26: (단위 :cm)
B27: 관측년도 | H27: 조위편차 | O27: 관측년도 | U27: 조위편차 | AB27: 관측년도 | AH27: 조위편차
B28: 1992 | H28: 0 | O28: 2002 | U28: 0.18 | AB28: 2012 | AH28: 0.18
B29: =B28+1 -> 1993 | H29: 0 | O29: =O28+1 -> 2003 | U29: 0.17 | AB29: =AB28+1 -> 2013 | AH29: 0.22
B30: =B29+1 -> 1994 | H30: 0 | O30: =O29+1 -> 2004 | U30: 0.17 | AB30: =AB29+1 -> 2014 | AH30: 0.19
B31: =B30+1 -> 1995 | H31: 0 | O31: =O30+1 -> 2005 | U31: 0.23 | AB31: =AB30+1 -> 2015 | AH31: 0.24
B32: =B31+1 -> 1996 | H32: 0 | O32: =O31+1 -> 2006 | U32: 0.25 | AB32: =AB31+1 -> 2016 | AH32: 0.32
B33: =B32+1 -> 1997 | H33: 0 | O33: =O32+1 -> 2007 | U33: 0.2 | AB33: =AB32+1 -> 2017 | AH33: 0.27
B34: =B33+1 -> 1998 | H34: 0 | O34: =O33+1 -> 2008 | U34: 0.2 | AB34: =AB33+1 -> 2018 | AH34: 0.21
B35: =B34+1 -> 1999 | H35: 0 | O35: =O34+1 -> 2009 | U35: 0.25 | AB35: =AB34+1 -> 2019 | AH35: 0.29
B36: =B35+1 -> 2000 | H36: 0.19 | O36: =O35+1 -> 2010 | U36: 0.28 | AB36: =AB35+1 -> 2020 | AH36: 0.36
B37: =B36+1 -> 2001 | H37: 0.22 | O37: =O36+1 -> 2011 | U37: 0.22 | AB37: =AB36+1 -> 2021 | AH37: 0.28
B39: 다) 50년빈도 폭풍해일고
B40: - 약최고고조위(App. H.H.W) + 폭풍해일고 = | T40: =P9 -> 3.356 | X40: + | Y40: 1.1 | AB40: = | AC40: =T40+Y40 -> 4.456
B41: 구 분 | K41: 폭풍해일고 | U41: 재현빈도 | AE41: 비 고
B42: 부산항 | K42: 110.0cm | U42: 50년
B44: 라) 설계 고조위
B45: - 조위 결정
...

Sheet 3.1.1 마루높이 결정(2)
A1: 나. 마루높이 검토
A2: 1) 마루높이 산정방법
B3: 구 분 | M3: 산정방법 | AD3: 비 고
B4: 항만 및 어항설계기준 에 의한 방법 | M4: 설계조위 + (0.6 ~ 1.25) H⅓
B5: 처오름높이에 의한 방법 | M5: R = Ho' × R/Ho' × γ × K
B6: 파고전달율에 의한 방법 | M6: HT = KTO × HI
B7: 인근 구조물 마루높이
B9: 2) 마루높이 결정
C10: 북측파제제
B11: 구 분 | O11: 100년 빈도 | AK11: 산정 마루높이
B12: 항만 및 어항 설계기준에 의한 방법 | O12: =AE36 -> 6.26 | X12: ~ | AA12: =AK36 -> 8.86 | AK12: 7.3
B13: 처오름 높이에 의한 방법 | O13: =AE80 -> 9.255
B14: 전달 파고에 의한 방법 | O14: =J128 -> 6
B15: 인근 구조물 마루높이 | O15: =O133 -> 7.18 | X15: ~ | AA15: =W133 -> 7.3
C17: 남측파제제
B18: 구 분 | O18: 100년 빈도 | AK18: 산정 마루높이
B19: 항만 및 어항 설계기준에 의한 방법 | O19: =AE37 -> 6.68 | X19: ~ | AA19: =AK37 -> 9.73 | AK19: 6.7
B20: 처오름 높이에 의한 방법 | O20: =AE81 -> 10.2
B21: 전달 파고에 의한 방법 | O21: =J129 -> 6.7
B22: 인근 구조물 마루높이 | O22: =O134 -> 6.59 | X22: ~ | AA22: =W134 -> 7
B24: 3) 마루높이 검토
C25: 가) 검토조건
B26: 구 분 | J26: 파고(H⅓) | O26: 주기(T⅓) | U26: 설계조위 | AB26: 전면수심 | AI26: 설계수심
B27: 북측파제제 | J27: ='3.1.1 마루높이 결정(1)'!L19 -> 4 | O27: ='3.1.1 마루높이 결정(1)'!Q19 -> 11.5 | U27: ='3.1.1 마루높이 결정(1)'!S63 -> 3.855 | AB27: ='3.1.1 마루높이 결정(1)'!W19 -> -5.1 | AI27: =U27-AB27 -> 8.955
B28: 남측파제제 | J28: ='3.1.1 마루높이 결정(1)'!L20 -> 4.7 | O28: ='3.1.1 마루높이 결정(1)'!Q20 -> 11.6 | U28: =U27 -> 3.855 | AB28: ='3.1.1 마루높이 결정(1)'!W20 -> -10.5 | AI28: =U28-AB28 -> 14.355
C31: 나) 마루높이 산정
C32: (1) 항만 및 어항설계기준에 의한 방법 (KDS 64 45 20 p.12 참조)
D33: 마루높이 = 설계조위 + (0.6~1.25) · H1/3
B35: 구 분 | J35: 파고(H⅓) | P35: 산정과정 | AE35: 마루높이
B36: 북측파제제 | J36: =J27 -> 4 | P36: =U27 -> 3.855 | S36: + | T36: 0.6 | V36: ~ | W36: 1.25 | Z36: × | AA36: =J36 -> 4 | AD36: = | AE36: =ROUND(P36+(T36*AA36),2) -> 6.26 | AJ36: ~ | AK36: =ROUND(P36+(W36*AA36),2) -> 8.86
B37: 남측파제제 | J37: =J28 -> 4.7 | P37: =U28 -> 3.855 | S37: + | T37: 0.6 | V37: ~ | W37: 1.25 | Z37: × | AA37: =J37 -> 4.7 | AD37: = | AE37: =ROUND(P37+(T37*AA37),2) -> 6.68 | AJ37: ~ | AK37: =ROUND(P37+(W37*AA37),2) -> 9.73
C38: (2) 처오름높이에 의한 방법 (KDS 64 10 10, p.93 참조)
C39: - 항만 및 어항설계기준상의 처오름높이 산정
D40: 1) 불투과성, 일정한 사면경사, 불규칙파시 처오름높이 산정(Mase, 1989)
B44: Rx | H44: Rmax | N44: R2% | T44: R1/10 | Z44: R1/3 | AF44: 평균R
B45: A | H45: 2.32 | N45: 1.86 | T45: 1.7 | Z45: 1.38 | AF45: 0.88
B46: B | H46: 0.77 | N46: 0.71 | T46: 0.71 | Z46: 0.7 | AF46: 0.69
N47: = | O47: =G53/SQRT((T53/AI53)) -> 0.11098205 | S47: (100년) | W47: (북측)
N48: = | O48: =G54/SQRT((T54/AI54)) -> 0.10244843 | S48: (100년) | W48: (남측)
S49: (채택)
...

Sheet 3.1.2 쇄파대 검토
A1: 3.1.2 쇄파대 검토 | AR1: *지우지말것
A2: 1) SPM에 의한 쇄파대산정
B3: 가) 산정조건
B4: 구 간 | L4: ='3.1.1 마루높이 결정(1)'!I24 -> Aprox.H.H.W | R4: 구조물 축조 수심 (Aprox.H.H.W 기준) | AB4: 파랑조건 | BF4: 전면수심
AB5: 파 고 | AG5: 주 기 | AL5: 심해파장 | AV5: 구간 길이
B6: 북측파제제 | L6: ='3.1.1 마루높이 결정(1)'!P24 -> 3.356 | R6: =L6-BF6 -> 8.456 | AB6: ='3.1.1 마루높이 결정(2)'!J27 -> 4 | AG6: ='3.1.1 마루높이 결정(2)'!O27 -> 11.5 | AL6: =ROUND(1.56*AG6^2,2) -> 206.31 | AV6: 70 | AY6: m | BF6: ='3.1.1 마루높이 결정(2)'!AB27 -> -5.1
B7: 남측파제제 | L7: ='3.1.1 마루높이 결정(1)'!P24 -> 3.356 | R7: =L7-BF7 -> 13.856 | AB7: ='3.1.1 마루높이 결정(2)'!J28 -> 4.7 | AG7: ='3.1.1 마루높이 결정(2)'!O28 -> 11.6 | AL7: =ROUND(1.56*AG7^2,2) -> 209.91 | AV7: 20 | AY7: m | BF7: ='3.1.1 마루높이 결정(2)'!AB28 -> -10.5
AV8: 20 | AY8: m
AR9: 총길이 : | AV9: =SUM(AV6:AX8) -> 110 | AY9: m | BA9: =ROUND((#REF!*#REF!+AV6*BF6+AV7*BF7+AV8*BF8)/AV9,2) -> #REF!
B10: 나) 환산심해파고산정
B11: 구 간 | L11: 종 류 | P11: 해저경사(m) | V11: ds/Lo | AB11: H1/3/Ho' | AI11: 환산심해파고(Ho')
AR12: m(적용)
B13: 북측파제제 | L13: 경사제 | P13: =AR13 -> 0.02 | V13: =ROUND(R6/AL6,4) -> 0.041 | AB13: =IF(L13="혼성제",VLOOKUP(V13,'C-1(혼성제)'!$A$3:$B$732,2),IF(L13="경사제",VLOOKUP(V13,'C-1(경사제)'!$A$3:$B$732,2),"에러..")) -> 1.059 | AI13: =ROUND(AB6/AB13,2) -> 3.78 | AR13: =AW16 -> 0.02
B14: 남측파제제 | L14: 경사제 | P14: =AR14 -> 0.02 | V14: =ROUND(R7/AL7,4) -> 0.066 | AB14: =IF(L14="혼성제",VLOOKUP(V14,'C-1(혼성제)'!$A$3:$B$732,2),IF(L14="경사제",VLOOKUP(V14,'C-1(경사제)'!$A$3:$B$732,2),"에러..")) -> 0.9793 | AI14: =ROUND(AB7/AB14,2) -> 4.8 | AR14: =AW16 -> 0.02
AR15: =BA16 -> 0.033
B16: 다) 쇄파수심 산정 | AR16: 기준 경사m : | AW16: 0.02 | AZ16: , | BA16: 0.033 | BD16: , | BE16: 0.05 | BH16: , | BI16: 0.1
AV17: ( | AW17: 1/50 | AZ17: , | BA17: 1/30 | BD17: , | BE17: 1/20 | BH17: , | BI17: 1/10 | BL17: )
E34: Shore Protection Manual p.7-7, Figure 7-3참조
B36: 구 간 | L36: Ho'/gT2 | V36: Hb/Ho' | AF36: 쇄파수심(Hb)
B38: 북측파제제 | L38: =ROUND(ABS(AI13)/(9.81*AG6^2),4) -> 0.0029 | V38: =+VLOOKUP(L38,'C-1(경사제)'!$L$3:$P$111,IF(AR13=0.02,2,IF(AR13=0.033,3,IF(AR13=0.05,4,IF(AR13=0.1,5,6)))),0) -> 1.22 | AF38: =V38*AI13 -> 4.6116
B39: 남측파제제 | L39: =ROUND(ABS(AI14)/(9.81*AG7^2),4) -> 0.0036 | V39: =+VLOOKUP(L39,'C-1(경사제)'!$L$3:$P$111,IF(AR14=0.02,2,IF(AR14=0.033,3,IF(AR14=0.05,4,IF(AR14=0.1,5,6)))),0) -> 1.165 | AF39: =V39*AI14 -> 5.592
D69: Shore Protection Manual p.7-7, Figure 7-2참조
B71: 구 간 | K71: Hb/gT2 | S71: α | Y71: β | AE71: (db)max (α×Hb) | AK71: (db)min (β×Hb)
AR73: m
B74: 북측파제제 | K74: =ROUND(ABS(AF38)/(9.81*AG6^2),4) -> 0.0036 | S74: =+VLOOKUP(K74,'C-1(경사제)'!$R$4:$S$183,2) -> 1.515 | Y74: =+VLOOKUP(K74,'C-1(경사제)'!$R$4:$X$183,IF(AR74=0.01,3,IF(AR74=0.02,4,IF(AR74=0.033,5,IF(AR74=0.05,6,IF(AR74=0.1,7,8))))),0) -> 1.14 | AE74: =ABS(S74*AF38) -> 6.986574 | AK74: =ABS(Y74*AF38) -> 5.257224 | AR74: =P13 -> 0.02
B75: 남측파제제 | K75: =ROUND(ABS(AF39)/(9.81*AG7^2),4) -> 0.0042 | S75: =+VLOOKUP(K75,'C-1(경사제)'!$R$4:$S$183,2) -> 1.52 | Y75: =+VLOOKUP(K75,'C-1(경사제)'!$R$4:$X$183,IF(AR75=0.01,3,IF(AR75=0.02,4,IF(AR75=0.033,5,IF(AR75=0.05,6,IF(AR75=0.1,7,8))))),0) -> 1.15 | AE75: =ABS(S75*AF39) -> 8.49984 | AK75: =ABS(Y75*AF39) -> 6.4308 | AR75: =P14 -> 0.02
AR76: =P15 -> 0
B78: 라) 쇄파대 판정
B79: 구 간 | K79: 구조물 축조 수심 | S79: 쇄파대 구간 | AH79: 쇄파대 판정
B80: 북측파제제 | K80: =R6 -> 8.456 | S80: =AK74 -> 5.257224 | Z80: ∼ | AA80: =AE74 -> 6.986574 | AH80: =IF(AND(K80>=S80, K80<=AA80),"쇄파대","비쇄파대") -> 비쇄파대
B81: 남측파제제 | K81: =R7 -> 13.856 | S81: =AK75 -> 6.4308 | Z81: ∼ | AA81: =AE75 -> 8.49984 | AH81: =IF(AND(K81>=S81, K81<=AA81),"쇄파대","비쇄파대") -> 비쇄파대
A84: 2) 항만 및 어항 설계기준에 의한 방법
D108: 항만 및 어항설계기준 (유의파고 최댓값이 출현하는 수심의 산정도_Goda)
B109: 가) 쇄파수심 산정
B110: 구 간 | K110: 심해파장 Lo | P110: 환산심해파고 Ho' | V110: 해저경사 m | AA110: Ho'/Lo | AF110: (h1/3)peak/Ho' | AL110: 쇄파수심 (h1/3)peak
AR111: h/LO | AV111: H/H'O | AZ111: H'O | BE111: 20 | BF111: 50 | BG111: 100
B112: 북측파제제 | K112: =AL6 -> 206.31 | P112: =AZ112 -> 2.03 | V112: =P13 -> 0.02 | AA112: =P112/K112 -> 0.0098395618 | AF112: =AV112 -> 1.97 | AL112: =AF112*P112 -> 3.9991 | AR112: =R6/K112 -> 0.040986864 | AV112: =BF112 -> 1.97 | AZ112: =ROUND(AB6/AV112,2) -> 2.03 | BE112: 1.81 | BF112: =ROUND(BG112+(($BG$111-$BF$111)*(BE112-BG112)/($BG$111-$BE$111)),2) -> 1.97 | BG112: 2.24 | BI112: H/H'O
B113: 남측파제제 | K113: =AL7 -> 209.91 | P113: =AZ113 -> 2.11 | V113: =P14 -> 0.02 | AA113: =P113/K113 -> 0.010051927 | AF113: =AV113 -> 2.23 | AL113: =AF113*P113 -> 4.7053 | AR113: =R7/K113 -> 0.066009242 | AV113: =BF113 -> 2.23 | AZ113: =ROUND(AB7/AV113,2) -> 2.11 | BE113: 2.03 | BF113: =ROUND(BG113+(($BG$111-$BF$111)*(BE113-BG113)/($BG$111-$BE$111)),2) -> 2.23 | BG113: 2.57 | BI113: H/H'O
B115: 나) 쇄파대 판정
B116: 구 간 | K116: 구조물 축조 수심 | S116: 도표에 의한 방법 | AH116: 쇄파대 판정
...

Sheet 라. 1) 마. 1)~2)
A1: 라. 입경(d) 산정
A2: 1) 파랑에 의한 이동입경(d) 산정
C3: ○ 방파제 전면수심(h)에서 표층 이동한계 입경은 사또･다나까 계산도표에 의해 산정함.
C12: 고조위
B13: Ho' | D13: = | E13: =#REF! -> #REF! | I13: = | J13: =ROUND(E13/E14,3) -> #REF! | O13: h | Q13: = | R13: =19.7+0.66 -> 20.36 | V13: = | W13: =ROUND(R13/R14,3) -> #REF! | AB13: d | AD13: = | AE13: 2e-05 | AJ13: d | AL13: = | AM13: =AE13*E14*1000 -> #REF!
B14: Lo | E14: =#REF! -> #REF! | O14: Ho' | R14: =$E$13 -> #REF! | AB14: Lo
C16: 저조위
B17: Ho' | D17: = | E17: =#REF! -> #REF! | I17: = | J17: =ROUND(E17/E18,3) -> #REF! | O17: h | Q17: = | R17: 19.7 | V17: = | W17: =ROUND(R17/R18,3) -> #REF! | AB17: d | AD17: = | AE17: 2e-05 | AJ17: d | AL17: = | AM17: =AE17*E18*1000 -> #REF!
B18: Lo | E18: =#REF! -> #REF! | O18: Ho' | R18: =$E$17 -> #REF! | AB18: Lo
C21: ○ 방파제 전면수심(h)에서 완전 이동한계 입경은 사또･다나까 계산도표에 의해 산정함.
C30: 고조위시
B31: Ho' | D31: = | E31: =#REF! -> #REF! | I31: = | J31: =ROUND(E31/E32,3) -> #REF! | O31: h | Q31: = | R31: =R13 -> 20.36 | V31: = | W31: =ROUND(R31/R32,3) -> #REF! | AB31: d | AD31: = | AE31: 3.2e-06 | AJ31: d | AL31: = | AM31: =AE31*E32*1000 -> #REF!
B32: Lo | E32: =#REF! -> #REF! | O32: Ho' | R32: =$E$31 -> #REF! | AB32: Lo
C34: 저조위시
B35: Ho' | D35: = | E35: =#REF! -> #REF! | I35: = | J35: =ROUND(E35/E36,3) -> #REF! | O35: h | Q35: = | R35: =R17 -> 19.7 | V35: = | W35: =ROUND(R35/R36,3) -> #REF! | AB35: d | AD35: = | AE35: 3.2e-06 | AJ35: d | AL35: = | AM35: =AE35*E36*1000 -> #REF!
B36: Lo | E36: =#REF! -> #REF! | O36: Ho' | R36: =$E$35 -> #REF! | AB36: Lo
C39: ○ 흐름에 대한 안정 입경(d) 산정
C41: 고조위시
X42: = | Y42: =(PI()*T47*AB48^6)/(48*R49^3*AH50^6*(Z51-1)^3*(COS(RADIANS(AA52))-SIN(RADIANS(AA52)))^3) -> #REF!
AG43: d | AI43: = | AJ43: =(Y42*(3/4)/T47/PI())^(1/3)*2*1000 -> #REF!
E46: 여기서, | I46: M | K46: : | L46: 사석 등의 안정질량(tf)
I47: ργ | K47: : | L47: 사석 등의 밀도( | T47: 2.65 | Y47: )
I48: U | K48: : | L48: 사석 등의 상부에서의 물의 유속( | AB48: =AD86 -> #REF! | AE48: m/sec)
I49: g | K49: : | L49: 중력 가속도( | R49: 9.81
I50: y | K50: : | L50: Isbash의 정수(파묻힌 돌은 | Y50: 1.2 | AB50: , 노출된 돌은 | AH50: 0.86 | AK50: )
I51: Sγ | K51: : | L51: 사석 등의 물에 대한 비중(= | Z51: =T47/1.03 -> 2.5728155 | AD51: )
I52: θ | K52: : | L52: 수로상의 축방향의 사면의 경사( | AA52: 33.69
C54: 저조위시 | BA54: =(COS(RADIANS(AA52))-SIN(RADIANS(AA52)))^3 -> 0.021335
X55: = | Y55: =(PI()*T60*AB61^6)/(48*R62^3*AH63^6*(Z64-1)^3*(COS(RADIANS(AA65))-SIN(RADIANS(AA65)))^3) -> 0.00013564173
AG56: d | AI56: = | AJ56: =((Y55/T60/PI()/(4/3))^(1/3))*2*1000 -> 46.066259
E59: 여기서, | I59: M | K59: : | L59: 사석 등의 안정질량(tf)
I60: ργ | K60: : | L60: 사석 등의 밀도( | T60: 2.65 | Y60: )
I61: U | K61: : | L61: 사석 등의 상부에서의 물의 유속( | AB61: 0.54 | AE61: m/sec)
I62: g | K62: : | L62: 중력 가속도( | R62: 9.81
I63: y | K63: : | L63: Isbash의 정수(파묻힌 돌은 | Y63: 1.2 | AB63: , 노출된 돌은 | AH63: 0.86 | AK63: )
I64: Sγ | K64: : | L64: 사석 등의 물에 대한 비중(= | Z64: =T60/1.03 -> 2.5728155 | AD64: )
I65: θ | K65: : | L65: 수로상의 축방향의 사면의 경사( | AA65: 33.69
AG66: 항설 202페이지
E68: ① 유속산정
E69: - 방파제저면에서 파의 최대수립자 속도(항만 및 어항설계기준, p47)
...

Sheet 1.1.2 쇄파대 검토(저조위)
A1: 나. 저조위(L.L.W)
A2: 1) SPM에 의한 쇄파대산정
B3: 가) 산정조건 | BL3: *주의해야됨
B4: 구 간 | L4: L.L.W | R4: 구조물 축조 수심 (Aprox.L.L.W 기준) | AB4: 파랑조건 | BF4: 전면수심 | BL4: 전구역평균수심
AB5: 파 고 | AG5: 주 기 | AL5: 심해파장 | AV5: 구간 길이 | BM5: DL(-) | BP5: 3 | BS5: m
B6: ='3.1.2 쇄파대 검토'!#REF! -> #REF! | L6: ='3.1.1 마루높이 결정(1)'!P32 -> 0 | R6: =L6-BF6 -> #REF! | AB6: ='3.1.2 쇄파대 검토'!#REF! -> #REF! | AG6: ='3.1.2 쇄파대 검토'!#REF! -> #REF! | AL6: =ROUND(1.56*AG6^2,2) -> #REF! | AV6: 30 | AY6: m | BF6: =#REF! -> #REF!
B7: ='3.1.2 쇄파대 검토'!B6:K6 -> 북측파제제 | L7: =L6 -> 0 | R7: =L7-BF7 -> #REF! | AB7: ='3.1.2 쇄파대 검토'!AB6:AF6 -> 4 | AG7: ='3.1.2 쇄파대 검토'!AG6:AK6 -> 11.5 | AL7: =ROUND(1.56*AG7^2,2) -> 206.31 | AV7: 70 | AY7: m | BF7: =#REF! -> #REF!
B8: ='3.1.2 쇄파대 검토'!#REF! -> #REF! | L8: =L7 -> 0 | R8: =L8-BF8 -> #REF! | AB8: ='3.1.2 쇄파대 검토'!#REF! -> #REF! | AG8: ='3.1.2 쇄파대 검토'!#REF! -> #REF! | AL8: =ROUND(1.56*AG8^2,2) -> #REF! | BF8: =#REF! -> #REF!
B9: ='3.1.2 쇄파대 검토'!B7:K7 -> 남측파제제 | L9: =L6 -> 0 | R9: =L9-BF9 -> #REF! | AB9: ='3.1.2 쇄파대 검토'!AB7:AF7 -> 4.7 | AG9: ='3.1.2 쇄파대 검토'!AG7:AK7 -> 11.6 | AL9: =ROUND(1.56*AG9^2,2) -> 209.91 | AV9: 20 | AY9: m | BF9: =#REF! -> #REF!
AV10: 20 | AY10: m | BF10: =#REF! -> #REF!
AR11: 총길이 : | AV11: =SUM(AV6:AX10) -> 140 | AY11: m
B12: 나) 환산심해파고산정
B13: 구 간 | L13: 종 류 | P13: 해저경사(m) | V13: ds/Lo | AB13: H1/3/Ho' | AI13: 환산심해파고(Ho')
AR14: m(적용)
B15: =B6 -> #REF! | L15: 혼성제 | P15: =AR15 -> 0.02 | V15: =ROUND(R6/AL6,4) -> #REF! | AB15: =IF(L15="혼성제",VLOOKUP(V15,'C-1(혼성제)'!$A$3:$B$732,2),IF(L15="경사제",VLOOKUP(V15,'C-1(경사제)'!$A$3:$B$732,2),"에러..")) -> #REF! | AI15: =ROUND(AB6/AB15,2) -> #REF! | AR15: =AW20 -> 0.02
B16: =B7 -> 북측파제제 | L16: =L15 -> 혼성제 | P16: =AR16 -> 0.02 | V16: =ROUND(R7/AL7,4) -> #REF! | AB16: =IF(L16="혼성제",VLOOKUP(V16,'C-1(혼성제)'!$A$3:$B$732,2),IF(L16="경사제",VLOOKUP(V16,'C-1(경사제)'!$A$3:$B$732,2),"에러..")) -> #REF! | AI16: =ROUND(AB7/AB16,2) -> #REF! | AR16: =AW20 -> 0.02
B17: =B8 -> #REF! | L17: =L16 -> 혼성제 | P17: =AR17 -> 0.02 | V17: =ROUND(R8/AL8,4) -> #REF! | AB17: =IF(L17="혼성제",VLOOKUP(V17,'C-1(혼성제)'!$A$3:$B$732,2),IF(L17="경사제",VLOOKUP(V17,'C-1(경사제)'!$A$3:$B$732,2),"에러..")) -> #REF! | AI17: =ROUND(AB8/AB17,2) -> #REF! | AR17: =AW20 -> 0.02
B18: =B9 -> 남측파제제 | L18: =L17 -> 혼성제 | P18: =AR18 -> 0.02 | V18: =ROUND(R9/AL9,4) -> #REF! | AB18: =IF(L18="혼성제",VLOOKUP(V18,'C-1(혼성제)'!$A$3:$B$732,2),IF(L18="경사제",VLOOKUP(V18,'C-1(경사제)'!$A$3:$B$732,2),"에러..")) -> #REF! | AI18: =ROUND(AB9/AB18,2) -> #REF! | AR18: =AW20 -> 0.02
AR19: =BA20 -> 0.033
B20: 다) 쇄파수심 산정 | AR20: 기준 경사m : | AW20: 0.02 | AZ20: , | BA20: 0.033 | BD20: , | BE20: 0.05 | BH20: , | BI20: 0.1
AV21: ( | AW21: 1/50 | AZ21: , | BA21: 1/30 | BD21: , | BE21: 1/20 | BH21: , | BI21: 1/10 | BL21: )
E37: Shore Protection Manual p.7-7, Figure 7-3참조
B39: 구 간 | L39: Ho'/gT2 | V39: Hb/Ho' | AF39: 쇄파수심(Hb)
B41: =B15 -> #REF! | L41: =ROUND(ABS(AI15)/(9.81*AG6^2),4) -> #REF! | V41: =+VLOOKUP(L41,'C-1(경사제)'!$L$3:$P$111,IF(AR16=0.02,2,IF(AR16=0.033,3,IF(AR16=0.05,4,IF(AR16=0.1,5,6)))),0) -> #REF! | AF41: =V41*AI15 -> #REF!
B42: =B16 -> 북측파제제 | L42: =ROUND(ABS(AI16)/(9.81*AG7^2),4) -> #REF! | V42: =+VLOOKUP(L42,'C-1(경사제)'!$L$3:$P$111,IF(AR17=0.02,2,IF(AR17=0.033,3,IF(AR17=0.05,4,IF(AR17=0.1,5,6)))),0) -> #REF! | AF42: =V42*AI16 -> #REF!
B43: =B17 -> #REF! | L43: =ROUND(ABS(AI17)/(9.81*AG8^2),4) -> #REF! | V43: =+VLOOKUP(L43,'C-1(경사제)'!$L$3:$P$111,IF(AR18=0.02,2,IF(AR18=0.033,3,IF(AR18=0.05,4,IF(AR18=0.1,5,6)))),0) -> #REF! | AF43: =V43*AI17 -> #REF!
B44: =B18 -> 남측파제제 | L44: =ROUND(ABS(AI18)/(9.81*AG9^2),4) -> #REF! | V44: =+VLOOKUP(L44,'C-1(경사제)'!$L$3:$P$111,IF(AR19=0.02,2,IF(AR19=0.033,3,IF(AR19=0.05,4,IF(AR19=0.1,5,6)))),0) -> #REF! | AF44: =V44*AI18 -> #REF!
D73: Shore Protection Manual p.7-7, Figure 7-2참조
B75: 구 간 | K75: Hb/gT2 | S75: α | Y75: β | AE75: (db)max (α×Hb) | AK75: (db)min (β×Hb)
AR77: m
B78: =B41 -> #REF! | K78: =ROUND(ABS(AF41)/(9.81*AG6^2),4) -> #REF! | S78: =+VLOOKUP(K78,'C-1(경사제)'!$R$4:$S$183,2) -> #REF! | Y78: =+VLOOKUP(K78,'C-1(경사제)'!$R$4:$X$183,IF(AR78=0.01,3,IF(AR78=0.02,4,IF(AR78=0.033,5,IF(AR78=0.05,6,IF(AR78=0.1,7,8))))),0) -> #REF! | AE78: =ABS(S78*AF41) -> #REF! | AK78: =ABS(Y78*AF41) -> #REF! | AR78: =P15 -> 0.02
B79: =B42 -> 북측파제제 | K79: =ROUND(ABS(AF42)/(9.81*AG7^2),4) -> #REF! | S79: =+VLOOKUP(K79,'C-1(경사제)'!$R$4:$S$183,2) -> #REF! | Y79: =+VLOOKUP(K79,'C-1(경사제)'!$R$4:$X$183,IF(AR79=0.01,3,IF(AR79=0.02,4,IF(AR79=0.033,5,IF(AR79=0.05,6,IF(AR79=0.1,7,8))))),0) -> #REF! | AE79: =ABS(S79*AF42) -> #REF! | AK79: =ABS(Y79*AF42) -> #REF! | AR79: =P16 -> 0.02
B80: =B43 -> #REF! | K80: =ROUND(ABS(AF43)/(9.81*AG8^2),4) -> #REF! | S80: =+VLOOKUP(K80,'C-1(경사제)'!$R$4:$S$183,2) -> #REF! | Y80: =+VLOOKUP(K80,'C-1(경사제)'!$R$4:$X$183,IF(AR80=0.01,3,IF(AR80=0.02,4,IF(AR80=0.033,5,IF(AR80=0.05,6,IF(AR80=0.1,7,8))))),0) -> #REF! | AE80: =ABS(S80*AF43) -> #REF! | AK80: =ABS(Y80*AF43) -> #REF! | AR80: =P17 -> 0.02
B81: =B44 -> 남측파제제 | K81: =ROUND(ABS(AF44)/(9.81*AG9^2),4) -> #REF! | S81: =+VLOOKUP(K81,'C-1(경사제)'!$R$4:$S$183,2) -> #REF! | Y81: =+VLOOKUP(K81,'C-1(경사제)'!$R$4:$X$183,IF(AR81=0.01,3,IF(AR81=0.02,4,IF(AR81=0.033,5,IF(AR81=0.05,6,IF(AR81=0.1,7,8))))),0) -> #REF! | AE81: =ABS(S81*AF44) -> #REF! | AK81: =ABS(Y81*AF44) -> #REF! | AR81: =P18 -> 0.02
AR82: =P19 -> 0
B84: 라) 쇄파대 판정
B85: 구 간 | K85: 구조물 축조 수심 | S85: 쇄파대 구간 | AH85: 쇄파대 판정
B86: =B78 -> #REF! | K86: =R6 -> #REF! | S86: =AK78 -> #REF! | Z86: ∼ | AA86: =AE78 -> #REF! | AH86: =IF(AND(K86>=S86, K86<=AA86),"쇄파대","비쇄파대") -> #REF!
B87: =B79 -> 북측파제제 | K87: =R7 -> #REF! | S87: =AK79 -> #REF! | Z87: ∼ | AA87: =AE79 -> #REF! | AH87: =IF(AND(K87>=S87, K87<=AA87),"쇄파대","비쇄파대") -> #REF!
B88: =B80 -> #REF! | K88: =R8 -> #REF! | S88: =AK80 -> #REF! | Z88: ∼ | AA88: =AE80 -> #REF! | AH88: =IF(AND(K88>=S88, K88<=AA88),"쇄파대","비쇄파대") -> #REF!
...

Sheet 3.1.3 피복재 소요중량
A1: 3.1.3 피복재 소요중량
A2: 1) 설계 제원 (H1/3, T1/3)
B3: 구 분 | I3: 파 고 (H1/3, m) | O3: 주 기 (T1/3, Sec) | U3: 약최고고조위 (Aprox.H.H.W) | AB3: 전면수심(m) | AH3: 비 고
B4: 북측파제제 | I4: ='3.1.1 마루높이 결정(1)'!L19 -> 4 | O4: ='3.1.1 마루높이 결정(1)'!Q19 -> 11.5 | U4: ='3.1.1 마루높이 결정(1)'!P24 -> 3.356 | AB4: ='3.1.1 마루높이 결정(2)'!AB27 -> -5.1
B5: 남측파제제 | I5: ='3.1.1 마루높이 결정(1)'!L20 -> 4.7 | O5: ='3.1.1 마루높이 결정(1)'!Q20 -> 11.6 | U5: =U4 -> 3.356 | AB5: ='3.1.1 마루높이 결정(2)'!AB28 -> -10.5
A7: 2) 피복재 소요질량 검토 방법
B8: 구 분 | L8: 산 정 방 법 | AA8: 비 고
B9: 허드슨 공식 | L9: Ns3 = KD·cotα
B10: Van Der Meer 공식 | L10: Ns = max(Nspl, Nssr)
B11: 다까하시·요시아 공식 | L11: Ns = CH{a(N0/N0.5)0.2+b}
A13: 3) 피복재 소요질량 검토 결과
B14: 구 분 | L14: 산 정 결 과 | AE14: 비 고
L15: 북측(100년) | V15: 남측(100년)
B16: 허드슨 공식 | L16: =AB56 -> 8 | V16: =AB59 -> 12.5 | AE16: T.T.P 적용시 (ton)
B17: Van Der Meer 공식 | L17: =AC90 -> 12.5 | V17: =AC98 -> 20
B18: 다까하시·요시아 공식 | L18: =AC140 -> 10 | V18: =AC148 -> 16
B19: 중간 피복재 | L19: =(L17/10)/2.65 -> 0.47169811 | V19: =(V17/10)/2.65 -> 0.75471698 | AE19: 외측 피복재 소요 중량의 1/10~1/15
A22: 나. 피복재 소요질량 산정
A23: 1) 허드슨 공식 (KDS 64 10 10, p.93 참조)
B24: ○ | C24: 파력을 받는 사면의 표면에 피복하는 사석 또는 블록의 안정질량
C25: 여기서, | I25: KD | J25: : 피복재 또는 피해율 등에 의해 결정되는 계수
I26: α | J26: : 사면의 경사각
B31: ○ | C31: 피복재 중량을 결정하기 위한 KD값
B32: 피 복 재 | N32: n | Q32: 거 치 | U32: 안정계수 KD | AG32: 비 고
U33: 쇄 파 | Z33: 비쇄파 | AD33: 경 사
B34: 매끈하고 둥근사석 | N34: 2 | Q34: 난적 | U34: 1.2 | Z34: 2.4 | AD34: 1.5~3.0
N35: 3 | Q35: =Q34 -> 난적 | U35: 1.6 | Z35: 3.2 | AD35: 〃
B36: 거칠고 모가 있는 돌 | AD36: 1.5
N37: 2 | Q37: 난적 | U37: 2 | Z37: 4 | AD37: 2
AD38: 3
N39: 3 | U39: 2.2 | Z39: 4.5
B40: 거칠고 모가 있는 돌 | N40: 2 | Q40: 특별한 것 | U40: 5.8 | Z40: 7
B41: 평면육면체 돌 | N41: 2 | Q41: =Q40 -> 특별한 것 | U41: 7.0~20.0 | Z41: 8.5~24.0
B42: 테트라포드(Tetrapod) 퀘드리포드(Quadripod) | N42: 2 | Q42: 난적 | U42: 7 | Z42: 8 | AD42: 1.5 2.0 3.0
B44: 트라이바(Tribar) | Q44: 난적 | AD44: 1.5
N45: 2 | U45: 9 | Z45: 10 | AD45: 2
AD46: 3
B47: 돌로스(Dolos) | N47: 2 | Q47: 난적 | U47: 15.8 | Z47: 31.8 | AD47: 2.0 3.0
B48: 모디파이드큐브 | N48: 2 | Q48: 난적 | U48: 6.5 | Z48: 7.5
B49: 헥사포드(Hexapod) | N49: 2 | U49: 8 | Z49: 9.5
...

Sheet 마),바)
A1: 마. 입경(d) 산정
A2: 1) 파랑에 의한 이동입경(d) 산정
C3: 가) 방파제 전면수심(h)에서 표층 이동한계 입경은 사또･다나까 계산도표에 의해 산정함.
B13: - 접속부
B14: Ho' | D14: = | E14: =#REF! -> #REF! | I14: = | J14: =ROUND(E14/E15,4) -> #REF! | O14: h | Q14: = | R14: =#REF! -> #REF! | V14: = | W14: =ROUND(R14/R15,2) -> #REF! | AB14: d | AD14: = | AE14: 8.7e-05 | AJ14: d | AL14: = | AM14: =ROUND(AE14*E15*1000,2) -> #REF!
B15: Lo | E15: =#REF! -> #REF! | O15: Ho' | R15: =$E$14 -> #REF! | AB15: Lo
B17: - 제간부 A
B18: Ho' | D18: = | E18: =#REF! -> #REF! | I18: = | J18: =ROUND(E18/E19,4) -> #REF! | O18: h | Q18: = | R18: =#REF! -> #REF! | V18: = | W18: =ROUND(R18/R19,2) -> #REF! | AB18: d | AD18: = | AE18: 1.5e-05 | AJ18: d | AL18: = | AM18: =ROUND(AE18*E19*1000,2) -> #REF!
B19: Lo | E19: =#REF! -> #REF! | O19: Ho' | R19: =$E$18 -> #REF! | AB19: Lo
B21: - 제간부 B
B22: Ho' | D22: = | E22: =#REF! -> #REF! | I22: = | J22: =ROUND(E22/E23,4) -> #REF! | O22: h | Q22: = | R22: =#REF! -> #REF! | V22: = | W22: =ROUND(R22/R23,2) -> #REF! | AB22: d | AD22: = | AE22: 5.7e-06 | AJ22: d | AL22: = | AM22: =ROUND(AE22*E23*1000,2) -> #REF!
B23: Lo | E23: =#REF! -> #REF! | O23: Ho' | R23: =$E$22 -> #REF! | AB23: Lo
B25: - 제두부
B26: Ho' | D26: = | E26: =#REF! -> #REF! | I26: = | J26: =ROUND(E26/E27,4) -> #REF! | O26: h | Q26: = | R26: =#REF! -> #REF! | V26: = | W26: =ROUND(R26/R27,2) -> #REF! | AB26: d | AD26: = | AE26: 5.4e-06 | AJ26: d | AL26: = | AM26: =ROUND(AE26*E27*1000,2) -> #REF!
B27: Lo | E27: =#REF! -> #REF! | O27: Ho' | R27: =$E$26 -> #REF! | AB27: Lo
C30: 나) 방파제 전면수심(h)에서 완전 이동한계 입경은 사또･다나까 계산도표에 의해 산정함.
B40: - 접속부
B41: Ho' | D41: = | E41: =E14 -> #REF! | I41: = | J41: =ROUND(E41/E42,4) -> #REF! | O41: h | Q41: = | R41: =R14 -> #REF! | V41: = | W41: =ROUND(R41/R42,2) -> #REF! | AB41: d | AD41: = | AE41: 3.1e-05 | AJ41: d | AL41: = | AM41: =ROUND(AE41*E42*1000,2) -> #REF!
B42: Lo | E42: =E15 -> #REF! | O42: Ho' | R42: =E41 -> #REF! | AB42: Lo
B44: - 제간부 A
B45: Ho' | D45: = | E45: =E18 -> #REF! | I45: = | J45: =ROUND(E45/E46,4) -> #REF! | O45: h | Q45: = | R45: =R18 -> #REF! | V45: = | W45: =ROUND(R45/R46,2) -> #REF! | AB45: d | AD45: = | AE45: 2.6e-06 | AJ45: d | AL45: = | AM45: =ROUND(AE45*E46*1000,2) -> #REF!
B46: Lo | E46: =E19 -> #REF! | O46: Ho' | R46: =E45 -> #REF! | AB46: Lo
B48: - 제간부 B
B49: Ho' | D49: = | E49: =E22 -> #REF! | I49: = | J49: =ROUND(E49/E50,4) -> #REF! | O49: h | Q49: = | R49: =R22 -> #REF! | V49: = | W49: =ROUND(R49/R50,2) -> #REF! | AB49: d | AD49: = | AE49: 1.3e-06 | AJ49: d | AL49: = | AM49: =ROUND(AE49*E50*1000,2) -> #REF!
B50: Lo | E50: =E23 -> #REF! | O50: Ho' | R50: =E49 -> #REF! | AB50: Lo
B52: - 제두부
B53: Ho' | D53: = | E53: =E26 -> #REF! | I53: = | J53: =ROUND(E53/E54,4) -> #REF! | O53: h | Q53: = | R53: =R26 -> #REF! | V53: = | W53: =ROUND(R53/R54,2) -> #REF! | AB53: d | AD53: = | AE53: 1.2e-06 | AJ53: d | AL53: = | AM53: =ROUND(AE53*E54*1000,2) -> #REF!
B54: Lo | E54: =E27 -> #REF! | O54: Ho' | R54: =E53 -> #REF! | AB54: Lo
A57: 바. 세굴방지공 결정
A58: 1) 단면규모 기준 - Berm Type
B59: 구 분 | H59: S.P.M에 의한 소단설치단면제원 | R59: 항만 및 어항설계기준 방파제단면제원(p.139) | AB59: TTP설계와 시공기준서 | AK59: 비 고
B61: 소 요 두 께 | H61: r ~ 2r | R61: 2r | AB61: 1.0m ~ 2.0m
B62: 소 요 소 단 폭 | H62: 3H ~ 4.5H | R62: 최소 3.0m | AB62: 3.0m ~ 5.0m
A64: 2) 단면규모 기준 - Buried Type
B65: 구 분 | H65: S.P.M에 의한 소단설치단면제원 | R65: 항만 및 어항설계기준 방파제단면제원(p.139) | AB65: TTP설계와 시공기준서 | AK65: 비 고
B67: 소 요 두 께 | H67: r ~ 2r | R67: 2r | AB67: 1.0m ~ 2.0m
B68: 소 요 소 단 폭 | H68: 2H ~ 3H | R68: 최소 3.0m | AB68: 3.0m ~ 5.0m
A70: 3) 세굴방지공 단면규모 산정
B71: 구 분 | M71: 소요두께 | W71: 소요소단폭 | AG71: 비 고
B72: =B80 -> #REF! | M72: 0.6 | W72: 3 | AG72: Berm Type
...

Sheet C-1(경사제)
A1: d/Lo | B1: H/Ho' | D1: Ho'/gT² | E1: R/Ho' | Z1: 해저 기울기 1/50일때 h/Ho' 와 Ho'/Lo 에 따른 Hmax/Ho' | AH1: 해저 기울기 1/50일때 h/Ho' 와 Ho'/Lo 에 따른 H1/20 / H1/3
D2: ds/Ho' | E2: 0.8 | F2: 0.8 | G2: 0.8 | H2: 2 | I2: 2 | J2: 2 | L2: m | M2: 0.02 | N2: 0.033 | O2: 0.05 | P2: 0.1 | R2: Hb'/gT² | S2: α | T2: β
A3: 0.0001 | B3: 4.467 | D3: Slope | E3: 1.3 | F3: 1.5 | G3: 2 | H3: 1.3 | I3: 1.5 | J3: 2 | L3: 0.0004 | M3: 2.08 | N3: 2.28 | O3: 2.42 | P3: 2.53 | T3: 0.01 | U3: 0.02 | V3: 0.033 | W3: 0.05 | X3: 0.1 | Z3: h/Ho' | AA3: Ho'/Lo | AH3: h/Ho' | AI3: Ho'/Lo
A4: 0.0002 | B4: 3.757 | D4: 0.0003 | E4: 5.69 | F4: 5.63 | G4: 5.53 | H4: 4.21 | I4: 4.11 | J4: 4.22 | L4: 0.0005 | M4: 1.96 | N4: 2.13 | O4: 2.26 | P4: 2.38 | R4: 0.0001 | S4: 1.475 | U4: 1.06 | V4: 0.99 | W4: 0.88 | X4: 0.725 | AA4: 0.002 | AB4: 0.005 | AC4: 0.01 | AD4: 0.02 | AE4: 0.04 | AF4: 0.08 | AI4: 0.002 | AJ4: 0.005 | AK4: 0.01 | AL4: 0.02 | AM4: 0.04 | AN4: 0.08
A5: 0.0003 | B5: 3.395 | D5: 0.0006 | E5: 5.4 | F5: 5.33 | G5: 5.25 | H5: 3.99 | I5: 3.93 | J5: 3.98 | L5: 0.0006 | M5: 1.86 | N5: 2.02 | O5: 2.13 | P5: 2.27 | R5: 0.0002 | S5: 1.475 | U5: 1.06 | V5: 0.995 | W5: 0.88 | X5: 0.73 | Z5: 0 | AA5: 0.69 | AB5: 0.46 | AC5: 0.34 | AD5: 0.25 | AE5: 0.2 | AF5: 0.16 | AH5: 0 | AI5: 1.452 | AJ5: 1.448 | AK5: 1.441 | AL5: 1.427 | AM5: 1.408 | AN5: 1.383
A6: 0.0004 | B6: 3.16 | D6: 0.0009 | E6: 5.05 | F6: 4.97 | G6: 4.85 | H6: 3.78 | I6: 3.83 | J6: 3.84 | L6: 0.0007 | M6: 1.78 | N6: 1.93 | O6: 2.04 | P6: 2.16 | R6: 0.0003 | S6: 1.475 | U6: 1.065 | V6: 1 | W6: 0.885 | X6: 0.735 | Z6: 0.1 | AA6: 0.72 | AB6: 0.51 | AC6: 0.39 | AD6: 0.31 | AE6: 0.26 | AF6: 0.21 | AH6: 0.1 | AI6: 1.439 | AJ6: 1.426 | AK6: 1.41 | AL6: 1.383 | AM6: 1.353 | AN6: 1.323
A7: 0.0005 | B7: 2.989 | D7: 0.0012 | E7: 4.79 | F7: 4.68 | G7: 4.46 | H7: 3.4 | I7: 3.59 | J7: 3.7 | L7: 0.0008 | M7: 1.72 | N7: 1.86 | O7: 1.96 | P7: 2.08 | R7: 0.0004 | S7: 1.475 | U7: 1.065 | V7: 1 | W7: 0.89 | X7: 0.74 | Z7: 0.2 | AA7: 0.77 | AB7: 0.56 | AC7: 0.45 | AD7: 0.37 | AE7: 0.32 | AF7: 0.27 | AH7: 0.2 | AI7: 1.422 | AJ7: 1.398 | AK7: 1.373 | AL7: 1.344 | AM7: 1.313 | AN7: 1.287
A8: 0.0006 | B8: 2.856 | D8: 0.0016 | E8: 4.53 | F8: 4.44 | G8: 4.12 | H8: 3.14 | I8: 3.26 | J8: 3.4 | L8: 0.0009 | M8: 1.66 | N8: 1.8 | O8: 1.9 | P8: 2.01 | R8: 0.0005 | S8: 1.48 | U8: 1.07 | V8: 1 | W8: 0.89 | X8: 0.74 | Z8: 0.3 | AA8: 0.81 | AB8: 0.62 | AC8: 0.51 | AD8: 0.43 | AE8: 0.38 | AF8: 0.33 | AH8: 0.3 | AI8: 1.404 | AJ8: 1.372 | AK8: 1.343 | AL8: 1.316 | AM8: 1.289 | AN8: 1.267
A9: 0.0007 | B9: 2.749 | D9: 0.0019 | E9: 4.29 | F9: 4.17 | G9: 3.86 | H9: 2.99 | I9: 3.16 | J9: 3.31 | L9: 0.001 | M9: 1.61 | N9: 1.75 | O9: 1.84 | P9: 1.96 | R9: 0.0006 | S9: 1.48 | U9: 1.07 | V9: 1.005 | W9: 0.895 | X9: 0.745 | Z9: 0.4 | AA9: 0.86 | AB9: 0.67 | AC9: 0.57 | AD9: 0.49 | AE9: 0.44 | AF9: 0.39 | AH9: 0.4 | AI9: 1.385 | AJ9: 1.349 | AK9: 1.321 | AL9: 1.296 | AM9: 1.274 | AN9: 1.257
A10: 0.0008 | B10: 2.659 | D10: 0.0023 | E10: 3.98 | F10: 3.87 | G10: 3.5 | H10: 2.8 | I10: 3 | J10: 3.13 | L10: 0.0011 | M10: 1.56 | N10: 1.7 | O10: 1.79 | P10: 1.91 | R10: 0.0007 | S10: 1.48 | U10: 1.075 | V10: 1.005 | W10: 0.9 | X10: 0.745 | Z10: 0.5 | AA10: 0.92 | AB10: 0.73 | AC10: 0.64 | AD10: 0.56 | AE10: 0.51 | AF10: 0.45 | AH10: 0.5 | AI10: 1.368 | AJ10: 1.332 | AK10: 1.306 | AL10: 1.283 | AM10: 1.265 | AN10: 1.25
A11: 0.0009 | B11: 2.582 | D11: 0.0031 | E11: 3.6 | F11: 3.46 | G11: 3.11 | H11: 2.51 | I11: 2.79 | J11: 2.85 | L11: 0.0012 | M11: 1.53 | N11: 1.65 | O11: 1.75 | P11: 1.86 | R11: 0.0008 | S11: 1.48 | U11: 1.075 | V11: 1.01 | W11: 0.9 | X11: 0.75 | Z11: 0.6 | AA11: 0.98 | AB11: 0.8 | AC11: 0.7 | AD11: 0.63 | AE11: 0.58 | AF11: 0.52 | AH11: 0.6 | AI11: 1.351 | AJ11: 1.316 | AK11: 1.293 | AL11: 1.275 | AM11: 1.259 | AN11: 1.246
A12: 0.001 | B12: 2.515 | D12: 0.0047 | E12: 3.06 | F12: 2.92 | G12: 2.59 | H12: 2.32 | I12: 2.57 | J12: 2.63 | L12: 0.0013 | M12: 1.49 | N12: 1.61 | O12: 1.71 | P12: 1.82 | R12: 0.0009 | S12: 1.485 | U12: 1.08 | V12: 1.01 | W12: 0.9 | X12: 0.75 | Z12: 0.7 | AA12: 1.04 | AB12: 0.86 | AC12: 0.77 | AD12: 0.7 | AE12: 0.65 | AF12: 0.58 | AH12: 0.7 | AI12: 1.338 | AJ12: 1.305 | AK12: 1.284 | AL12: 1.268 | AM12: 1.255 | AN12: 1.243
A13: 0.0011 | B13: 2.456 | D13: 0.0062 | E13: 2.69 | F13: 2.54 | G13: 2.11 | H13: 2.09 | I13: 2.41 | J13: 2.32 | L13: 0.0014 | M13: 1.46 | N13: 1.58 | O13: 1.68 | P13: 1.78 | R13: 0.001 | S13: 1.485 | U13: 1.085 | V13: 1.015 | W13: 0.9 | X13: 0.75 | Z13: 0.8 | AA13: 1.1 | AB13: 0.93 | AC13: 0.84 | AD13: 0.77 | AE13: 0.72 | AF13: 0.64 | AH13: 0.8 | AI13: 1.326 | AJ13: 1.297 | AK13: 1.278 | AL13: 1.265 | AM13: 1.253 | AN13: 1.242
A14: 0.0012 | B14: 2.404 | D14: 0.0078 | E14: 2.4 | F14: 2.25 | G14: 1.84 | H14: 1.92 | I14: 2.25 | J14: 2.1 | L14: 0.0015 | M14: 1.43 | N14: 1.55 | O14: 1.65 | P14: 1.75 | R14: 0.0011 | S14: 1.485 | U14: 1.09 | V14: 1.02 | W14: 0.905 | X14: 0.75 | Z14: 0.9 | AA14: 1.17 | AB14: 1 | AC14: 0.92 | AD14: 0.84 | AE14: 0.79 | AF14: 0.7 | AH14: 0.9 | AI14: 1.316 | AJ14: 1.288 | AK14: 1.273 | AL14: 1.261 | AM14: 1.252 | AN14: 1.243
A15: 0.0013 | B15: 2.357 | D15: 0.0093 | E15: 2.15 | F15: 1.98 | G15: 1.62 | H15: 1.85 | I15: 2.11 | J15: 1.85 | L15: 0.0016 | M15: 1.41 | N15: 1.52 | O15: 1.62 | P15: 1.72 | R15: 0.0012 | S15: 1.485 | U15: 1.095 | V15: 1.02 | W15: 0.905 | X15: 0.755 | Z15: 1 | AA15: 1.23 | AB15: 1.07 | AC15: 0.99 | AD15: 0.91 | AE15: 0.85 | AF15: 0.75 | AH15: 1 | AI15: 1.308 | AJ15: 1.283 | AK15: 1.269 | AL15: 1.26 | AM15: 1.253 | AN15: 1.244
A16: 0.0014 | B16: 2.314 | D16: 0.0124 | E16: 1.86 | F16: 1.76 | G16: 1.38 | H16: 1.71 | I16: 1.94 | J16: 1.61 | L16: 0.0017 | M16: 1.39 | N16: 1.5 | O16: 1.6 | P16: 1.69 | R16: 0.0013 | S16: 1.49 | U16: 1.1 | V16: 1.025 | W16: 0.91 | X16: 0.76 | Z16: 1.1 | AA16: 1.3 | AB16: 1.14 | AC16: 1.06 | AD16: 0.98 | AE16: 0.92 | AF16: 0.81 | AH16: 1.1 | AI16: 1.301 | AJ16: 1.278 | AK16: 1.266 | AL16: 1.259 | AM16: 1.255 | AN16: 1.248
A17: 0.0015 | B17: 2.275 | L17: 0.0018 | M17: 1.37 | N17: 1.47 | O17: 1.57 | P17: 1.67 | R17: 0.0014 | S17: 1.49 | U17: 1.1 | V17: 1.025 | W17: 0.91 | X17: 0.765 | Z17: 1.2 | AA17: 1.37 | AB17: 1.22 | AC17: 1.14 | AD17: 1.05 | AE17: 0.98 | AF17: 0.86 | AH17: 1.2 | AI17: 1.295 | AJ17: 1.274 | AK17: 1.265 | AL17: 1.261 | AM17: 1.259 | AN17: 1.252
A18: 0.0016 | B18: 2.239 | L18: 0.0019 | M18: 1.35 | N18: 1.45 | O18: 1.55 | P18: 1.64 | R18: 0.0015 | S18: 1.49 | U18: 1.1 | V18: 1.025 | W18: 0.915 | X18: 0.77 | Z18: 1.3 | AA18: 1.43 | AB18: 1.29 | AC18: 1.21 | AD18: 1.13 | AE18: 1.04 | AF18: 0.91 | AH18: 1.3 | AI18: 1.29 | AJ18: 1.272 | AK18: 1.264 | AL18: 1.262 | AM18: 1.265 | AN18: 1.257
A19: 0.0017 | B19: 2.205 | L19: 0.002 | M19: 1.33 | N19: 1.43 | O19: 1.53 | P19: 1.62 | R19: 0.0016 | S19: 1.49 | U19: 1.105 | V19: 1.025 | W19: 0.915 | X19: 0.775 | Z19: 1.4 | AA19: 1.5 | AB19: 1.37 | AC19: 1.29 | AD19: 1.2 | AE19: 1.1 | AF19: 0.95 | AH19: 1.4 | AI19: 1.285 | AJ19: 1.27 | AK19: 1.264 | AL19: 1.267 | AM19: 1.272 | AN19: 1.265
A20: 0.0018 | B20: 2.174 | D20: ds/Ho' >3.0 일경우(사석경사면) | L20: 0.0021 | M20: 1.31 | N20: 1.41 | O20: 1.51 | P20: 1.6 | R20: 0.0017 | S20: 1.495 | U20: 1.105 | V20: 1.03 | W20: 0.92 | X20: 0.775 | Z20: 1.5 | AA20: 1.58 | AB20: 1.44 | AC20: 1.36 | AD20: 1.27 | AE20: 1.16 | AF20: 1 | AH20: 1.5 | AI20: 1.282 | AJ20: 1.269 | AK20: 1.265 | AL20: 1.273 | AM20: 1.283 | AN20: 1.273
A21: 0.0019 | B21: 2.145 | D21: Ho'/gT² | E21: R/Ho' | L21: 0.0022 | M21: 1.3 | N21: 1.4 | O21: 1.5 | P21: 1.58 | R21: 0.0018 | S21: 1.495 | U21: 1.105 | V21: 1.03 | W21: 0.92 | X21: 0.775 | Z21: 1.6 | AA21: 1.65 | AB21: 1.52 | AC21: 1.44 | AD21: 1.34 | AE21: 1.22 | AF21: 1.05 | AH21: 1.6 | AI21: 1.279 | AJ21: 1.268 | AK21: 1.267 | AL21: 1.28 | AM21: 1.295 | AN21: 1.282
A22: 0.002 | B22: 2.119 | E22: SLOPE=1.5 | F22: SLOPE=2.0 | G22: SLOPE=2.5 | L22: 0.0023 | M22: 1.29 | N22: 1.385 | O22: 1.485 | P22: 1.56 | R22: 0.0019 | S22: 1.495 | U22: 1.11 | V22: 1.035 | W22: 0.925 | X22: 0.775 | Z22: 1.7 | AA22: 1.72 | AB22: 1.59 | AC22: 1.51 | AD22: 1.4 | AE22: 1.28 | AF22: 1.09 | AH22: 1.7 | AI22: 1.277 | AJ22: 1.268 | AK22: 1.271 | AL22: 1.289 | AM22: 1.307 | AN22: 1.29
A23: 0.0021 | B23: 2.094 | D23: 0.0004 | E23: 0.833 | F23: 0.924 | G23: 0.799 | L23: 0.0024 | M23: 1.275 | N23: 1.37 | O23: 1.465 | P23: 1.54 | R23: 0.002 | S23: 1.495 | U23: 1.11 | V23: 1.035 | W23: 0.925 | X23: 0.78 | Z23: 1.8 | AA23: 1.8 | AB23: 1.67 | AC23: 1.59 | AD23: 1.47 | AE23: 1.33 | AF23: 1.13 | AH23: 1.8 | AI23: 1.274 | AJ23: 1.268 | AK23: 1.277 | AL23: 1.3 | AM23: 1.32 | AN23: 1.298
A24: 0.0022 | B24: 2.07 | D24: 0.0005 | E24: 0.853 | F24: 0.957 | G24: 0.842 | L24: 0.0025 | M24: 1.26 | N24: 1.36 | O24: 1.45 | P24: 1.53 | R24: 0.0021 | S24: 1.5 | U24: 1.115 | V24: 1.04 | W24: 0.925 | X24: 0.78 | Z24: 1.9 | AA24: 1.87 | AB24: 1.74 | AC24: 1.66 | AD24: 1.53 | AE24: 1.38 | AF24: 1.17 | AH24: 1.9 | AI24: 1.272 | AJ24: 1.27 | AK24: 1.284 | AL24: 1.313 | AM24: 1.334 | AN24: 1.306
A25: 0.0023 | B25: 2.047 | D25: 0.0006 | E25: 0.87 | F25: 0.981 | G25: 0.875 | L25: 0.0026 | M25: 1.25 | N25: 1.35 | O25: 1.44 | P25: 1.51 | R25: 0.0022 | S25: 1.5 | U25: 1.115 | V25: 1.04 | W25: 0.925 | X25: 0.785 | Z25: 2 | AA25: 1.95 | AB25: 1.82 | AC25: 1.73 | AD25: 1.59 | AE25: 1.42 | AF25: 1.21 | AH25: 2 | AI25: 1.271 | AJ25: 1.272 | AK25: 1.291 | AL25: 1.326 | AM25: 1.346 | AN25: 1.314
A26: 0.0024 | B26: 2.025 | D26: 0.0008 | E26: 0.895 | F26: 1.029 | G26: 0.925 | L26: 0.0027 | M26: 1.24 | N26: 1.34 | O26: 1.425 | P26: 1.5 | R26: 0.0023 | S26: 1.5 | U26: 1.115 | V26: 1.045 | W26: 0.93 | X26: 0.785 | Z26: 2.1 | AA26: 2.02 | AB26: 1.89 | AC26: 1.8 | AD26: 1.64 | AE26: 1.46 | AF26: 1.24 | AH26: 2.1 | AI26: 1.271 | AJ26: 1.275 | AK26: 1.301 | AL26: 1.34 | AM26: 1.357 | AN26: 1.321
A27: 0.0025 | B27: 2.005 | D27: 0.001 | E27: 0.92 | F27: 1.058 | G27: 0.969 | L27: 0.0028 | M27: 1.23 | N27: 1.33 | O27: 1.41 | P27: 1.49 | R27: 0.0024 | S27: 1.5 | U27: 1.12 | V27: 1.045 | W27: 0.93 | X27: 0.79 | Z27: 2.2 | AA27: 2.1 | AB27: 1.97 | AC27: 1.86 | AD27: 1.69 | AE27: 1.5 | AF27: 1.27 | AH27: 2.2 | AI27: 1.27 | AJ27: 1.279 | AK27: 1.311 | AL27: 1.352 | AM27: 1.368 | AN27: 1.329
A28: 0.0026 | B28: 1.986 | D28: 0.0015 | E28: 0.972 | F28: 1.104 | G28: 1.075 | L28: 0.0029 | M28: 1.22 | N28: 1.31 | O28: 1.4 | P28: 1.475 | R28: 0.0025 | S28: 1.505 | U28: 1.12 | V28: 1.05 | W28: 0.935 | X28: 0.79 | Z28: 2.3 | AA28: 2.18 | AB28: 2.05 | AC28: 1.92 | AD28: 1.73 | AE28: 1.53 | AF28: 1.3 | AH28: 2.3 | AI28: 1.27 | AJ28: 1.284 | AK28: 1.323 | AL28: 1.362 | AM28: 1.377 | AN28: 1.335
A29: 0.0027 | B29: 1.967 | D29: 0.002 | E29: 1.014 | F29: 1.104 | G29: 1.05 | L29: 0.003 | M29: 1.21 | N29: 1.3 | O29: 1.39 | P29: 1.46 | R29: 0.0026 | S29: 1.505 | U29: 1.12 | V29: 1.05 | W29: 0.935 | X29: 0.795 | Z29: 2.4 | AA29: 2.25 | AB29: 2.12 | AC29: 1.97 | AD29: 1.76 | AE29: 1.56 | AF29: 1.33 | AH29: 2.4 | AI29: 1.271 | AJ29: 1.292 | AK29: 1.334 | AL29: 1.369 | AM29: 1.383 | AN29: 1.342
A30: 0.0028 | B30: 1.95 | D30: 0.003 | E30: 1.032 | F30: 1.04 | G30: 1.008 | J30: · | L30: 0.0031 | M30: 1.2 | N30: 1.3 | O30: 1.38 | P30: 1.45 | R30: 0.0027 | S30: 1.505 | U30: 1.125 | V30: 1.05 | W30: 0.94 | X30: 0.8 | Z30: 2.5 | AA30: 2.33 | AB30: 2.19 | AC30: 2.02 | AD30: 1.79 | AE30: 1.59 | AF30: 1.36 | AH30: 2.5 | AI30: 1.272 | AJ30: 1.299 | AK30: 1.345 | AL30: 1.376 | AM30: 1.388 | AN30: 1.348
A31: 0.0029 | B31: 1.933 | D31: 0.004 | E31: 0.996 | F31: 0.976 | G31: 0.944 | L31: 0.0032 | M31: 1.19 | N31: 1.29 | O31: 1.37 | P31: 1.44 | R31: 0.0028 | S31: 1.505 | U31: 1.125 | V31: 1.05 | W31: 0.94 | X31: 0.8 | Z31: 2.6 | AA31: 2.4 | AB31: 2.26 | AC31: 2.06 | AD31: 1.81 | AE31: 1.6 | AF31: 1.38 | AH31: 2.6 | AI31: 1.273 | AJ31: 1.308 | AK31: 1.354 | AL31: 1.38 | AM31: 1.392 | AN31: 1.354
A32: 0.003 | B32: 1.917 | D32: 0.005 | E32: 0.957 | F32: 0.925 | G32: 0.885 | L32: 0.0033 | M32: 1.18 | N32: 1.28 | O32: 1.36 | P32: 1.43 | R32: 0.0029 | S32: 1.51 | U32: 1.125 | V32: 1.05 | W32: 0.945 | X32: 0.8 | Z32: 2.7 | AA32: 2.47 | AB32: 2.33 | AC32: 2.08 | AD32: 1.82 | AE32: 1.62 | AF32: 1.41 | AH32: 2.7 | AI32: 1.276 | AJ32: 1.317 | AK32: 1.362 | AL32: 1.383 | AM32: 1.395 | AN32: 1.359
A33: 0.0031 | B33: 1.902 | D33: 0.006 | E33: 0.916 | F33: 0.884 | G33: 0.829 | L33: 0.0034 | M33: 1.175 | N33: 1.27 | O33: 1.35 | P33: 1.42 | R33: 0.003 | S33: 1.51 | U33: 1.13 | V33: 1.055 | W33: 0.945 | X33: 0.8 | Z33: 2.8 | AA33: 2.54 | AB33: 2.39 | AC33: 2.11 | AD33: 1.82 | AE33: 1.63 | AF33: 1.43 | AH33: 2.8 | AI33: 1.278 | AJ33: 1.326 | AK33: 1.368 | AL33: 1.385 | AM33: 1.397 | AN33: 1.363
A34: 0.0032 | B34: 1.887 | D34: 0.008 | E34: 0.832 | F34: 0.792 | G34: 0.718 | L34: 0.0035 | M34: 1.17 | N34: 1.26 | O34: 1.34 | P34: 1.41 | R34: 0.0031 | S34: 1.51 | U34: 1.13 | V34: 1.055 | W34: 0.95 | X34: 0.805 | Z34: 2.9 | AA34: 2.62 | AB34: 2.45 | AC34: 2.12 | AD34: 1.83 | AE34: 1.64 | AF34: 1.45 | AH34: 2.9 | AI34: 1.283 | AJ34: 1.336 | AK34: 1.372 | AL34: 1.387 | AM34: 1.398 | AN34: 1.367
A35: 0.0033 | B35: 1.873 | D35: 0.01 | E35: 0.755 | F35: 0.719 | G35: 0.639 | L35: 0.0036 | M35: 1.165 | N35: 1.255 | O35: 1.33 | P35: 1.4 | R35: 0.0032 | S35: 1.51 | U35: 1.13 | V35: 1.055 | W35: 0.95 | X35: 0.805 | Z35: 3 | AA35: 2.69 | AB35: 2.5 | AC35: 2.13 | AD35: 1.83 | AE35: 1.66 | AF35: 1.47 | AH35: 3 | AI35: 1.287 | AJ35: 1.343 | AK35: 1.376 | AL35: 1.389 | AM35: 1.399 | AN35: 1.37
A36: 0.0034 | B36: 1.86 | D36: 0.015 | E36: 0.613 | F36: 0.579 | G36: 0.495 | L36: 0.0037 | M36: 1.16 | N36: 1.25 | O36: 1.32 | P36: 1.39 | R36: 0.0033 | S36: 1.511 | T36: 1.201 | U36: 1.135 | V36: 1.06 | W36: 0.95 | X36: 0.81 | Z36: 3.1 | AA36: 2.77 | AB36: 2.53 | AC36: 2.13 | AD36: 1.82 | AE36: 1.66 | AF36: 1.49 | AH36: 3.1 | AI36: 1.291 | AJ36: 1.35 | AK36: 1.379 | AL36: 1.392 | AM36: 1.4 | AN36: 1.373
A37: 0.0035 | B37: 1.847 | D37: 0.02 | E37: 0.513 | F37: 0.47 | G37: 0.404 | L37: 0.0038 | M37: 1.15 | N37: 1.24 | O37: 1.31 | P37: 1.38 | R37: 0.0034 | S37: 1.513 | T37: 1.202 | U37: 1.135 | V37: 1.06 | W37: 0.95 | X37: 0.81 | Z37: 3.2 | AA37: 2.85 | AB37: 2.55 | AC37: 2.13 | AD37: 1.82 | AE37: 1.66 | AF37: 1.5 | AH37: 3.2 | AI37: 1.297 | AJ37: 1.355 | AK37: 1.382 | AL37: 1.393 | AM37: 1.4 | AN37: 1.376
A38: 0.0036 | B38: 1.834 | L38: 0.0039 | M38: 1.14 | N38: 1.235 | O38: 1.3 | P38: 1.37 | R38: 0.0035 | S38: 1.515 | T38: 1.202 | U38: 1.14 | V38: 1.06 | W38: 0.95 | X38: 0.815 | Z38: 3.3 | AA38: 2.92 | AB38: 2.56 | AC38: 2.12 | AD38: 1.81 | AE38: 1.67 | AF38: 1.52 | AH38: 3.3 | AI38: 1.303 | AJ38: 1.36 | AK38: 1.384 | AL38: 1.394 | AM38: 1.401 | AN38: 1.379
A39: 0.0037 | B39: 1.822 | L39: 0.004 | M39: 1.14 | N39: 1.23 | O39: 1.3 | P39: 1.36 | R39: 0.0036 | S39: 1.515 | T39: 1.203 | U39: 1.14 | V39: 1.065 | W39: 0.955 | X39: 0.815 | Z39: 3.4 | AA39: 2.98 | AB39: 2.56 | AC39: 2.12 | AD39: 1.8 | AE39: 1.67 | AF39: 1.54 | AH39: 3.4 | AI39: 1.309 | AJ39: 1.363 | AK39: 1.386 | AL39: 1.395 | AM39: 1.401 | AN39: 1.381
A40: 0.0038 | B40: 1.81 | L40: 0.0041 | M40: 1.13 | N40: 1.225 | O40: 1.29 | P40: 1.355 | R40: 0.0037 | S40: 1.516 | T40: 1.204 | U40: 1.14 | V40: 1.065 | W40: 0.955 | X40: 0.82 | Z40: 3.5 | AA40: 3.05 | AB40: 2.55 | AC40: 2.1 | AD40: 1.79 | AE40: 1.67 | AF40: 1.55 | AH40: 3.5 | AI40: 1.316 | AJ40: 1.367 | AK40: 1.388 | AL40: 1.397 | AM40: 1.401 | AN40: 1.383
...

Sheet C-1(혼성제)
A1: d/Lo | B1: H/Ho' | D1: R/Hi | E1: d/h | J1: 유의파고가 최대치로 출현하는 수심 산정도 | P1: 수심 주기 파장 | Y1: 해저 기울기 1/50일때 h/Ho' 와 Ho'/Lo 에 따른 Hmax/Ho' | AG1: 해저 기울기 1/50일때 h/Ho' 와 Ho'/Lo 에 따른 H1/20 / H1/3
E2: 0.7 | F2: 0.5 | G2: 0.3 | H2: 0 | P2: 주기 | Q2: 10 | R2: 11 | S2: 12 | T2: 13 | U2: 14 | V2: 15 | W2: 16 | X2: 18
A3: 0.0001 | B3: 4.467 | D3: -2.4 | E3: 0.9998 | J3: Ho'/Lo' | K3: 해저경사1:m | P3: 수심 | Q3: 파장 | R3: 파장 | S3: 파장 | T3: 파장 | U3: 파장 | V3: 파장 | W3: 파장 | X3: 파장 | Y3: h/Ho' | Z3: Ho'/Lo | AG3: h/Ho' | AH3: Ho'/Lo
A4: 0.0002 | B4: 3.757 | D4: -2.3 | E4: 0.9899 | K4: 10 | L4: 20 | M4: 30 | N4: 100 | P4: 8 | Q4: 83.82 | R4: 93.11 | S4: 102.33 | T4: 111.5 | U4: 120.62 | V4: 129.71 | W4: 138.77 | X4: 156.82 | Z4: 0.002 | AA4: 0.005 | AB4: 0.01 | AC4: 0.02 | AD4: 0.04 | AE4: 0.08 | AH4: 0.002 | AI4: 0.005 | AJ4: 0.01 | AK4: 0.02 | AL4: 0.04 | AM4: 0.08
A5: 0.0003 | B5: 3.395 | D5: -2.3 | E5: 0.99 | J5: 0.002 | K5: 2.855 | L5: 3.3 | M5: 3.494 | N5: 3.731 | P5: 9 | Q5: 88.27 | R5: 98.18 | S5: 108.01 | T5: 117.78 | U5: 127.49 | V5: 137.15 | W5: 146.79 | X5: 165.98 | Y5: 0 | Z5: 0.69 | AA5: 0.46 | AB5: 0.34 | AC5: 0.25 | AD5: 0.2 | AE5: 0.16 | AG5: 0 | AH5: 1.452 | AI5: 1.448 | AJ5: 1.441 | AK5: 1.427 | AL5: 1.408 | AM5: 1.383
A6: 0.0004 | B6: 3.16 | D6: -2.2 | E6: 0.9802 | J6: 0.0025 | K6: 2.676 | L6: 3.109 | M6: 3.298 | N6: 3.503 | P6: 10 | Q6: 92.37 | R6: 102.89 | S6: 113.3 | T6: 123.63 | U6: 133.91 | V6: 144.13 | W6: 154.31 | X6: 174.58 | Y6: 0.1 | Z6: 0.72 | AA6: 0.51 | AB6: 0.39 | AC6: 0.31 | AD6: 0.26 | AE6: 0.21 | AG6: 0.1 | AH6: 1.439 | AI6: 1.426 | AJ6: 1.41 | AK6: 1.383 | AL6: 1.353 | AM6: 1.323
A7: 0.0005 | B7: 2.989 | D7: -2.1 | E7: 0.9687 | J7: 0.003 | K7: 2.536 | L7: 2.936 | M7: 3.123 | N7: 3.318 | P7: 12 | Q7: 99.73 | R7: 111.38 | S7: 122.89 | T7: 134.31 | U7: 145.64 | V7: 156.91 | W7: 168.13 | X7: 190.44 | Y7: 0.2 | Z7: 0.77 | AA7: 0.56 | AB7: 0.45 | AC7: 0.37 | AD7: 0.32 | AE7: 0.27 | AG7: 0.2 | AH7: 1.422 | AI7: 1.398 | AJ7: 1.373 | AK7: 1.344 | AL7: 1.313 | AM7: 1.287
A8: 0.0006 | B8: 2.856 | D8: -2 | E8: 0.9553 | J8: 0.0035 | K8: 2.432 | L8: 2.81 | M8: 2.987 | N8: 3.183 | P8: 14 | Q8: 106.14 | R8: 118.86 | S8: 131.42 | T8: 143.85 | U8: 156.18 | V8: 168.43 | W8: 180.61 | X8: 204.82 | Y8: 0.3 | Z8: 0.81 | AA8: 0.62 | AB8: 0.51 | AC8: 0.43 | AD8: 0.38 | AE8: 0.33 | AG8: 0.3 | AH8: 1.404 | AI8: 1.372 | AJ8: 1.343 | AK8: 1.316 | AL8: 1.289 | AM8: 1.267
A9: 0.0007 | B9: 2.749 | D9: -1.9 | E9: 0.9395 | J9: 0.004 | K9: 2.341 | L9: 2.701 | M9: 2.865 | N9: 3.056 | P9: 16 | Q9: 111.78 | R9: 125.54 | S9: 139.09 | T9: 152.48 | U9: 165.76 | V9: 178.93 | W9: 192.02 | X9: 218.02 | Y9: 0.4 | Z9: 0.86 | AA9: 0.67 | AB9: 0.57 | AC9: 0.49 | AD9: 0.44 | AE9: 0.39 | AG9: 0.4 | AH9: 1.385 | AI9: 1.349 | AJ9: 1.321 | AK9: 1.296 | AL9: 1.274 | AM9: 1.257
A10: 0.0008 | B10: 2.659 | D10: -1.8 | E10: 0.9233 | J10: 0.0045 | K10: 2.274 | L10: 2.617 | M10: 2.775 | N10: 2.956 | P10: 18 | Q10: 116.79 | R10: 131.53 | S10: 146.03 | T10: 160.35 | U10: 174.53 | V10: 188.59 | W10: 202.55 | X10: 230.25 | Y10: 0.5 | Z10: 0.92 | AA10: 0.73 | AB10: 0.64 | AC10: 0.56 | AD10: 0.51 | AE10: 0.45 | AG10: 0.5 | AH10: 1.368 | AI10: 1.332 | AJ10: 1.306 | AK10: 1.283 | AL10: 1.265 | AM10: 1.25
A11: 0.0009 | B11: 2.582 | D11: -1.7 | E11: 0.9048 | J11: 0.005 | K11: 2.207 | L11: 2.533 | M11: 2.686 | N11: 2.869 | P11: 20 | Q11: 121.24 | R11: 136.93 | S11: 152.36 | T11: 167.57 | U11: 182.62 | V11: 197.53 | W11: 212.33 | X11: 241.66 | Y11: 0.6 | Z11: 0.98 | AA11: 0.8 | AB11: 0.7 | AC11: 0.63 | AD11: 0.58 | AE11: 0.52 | AG11: 0.6 | AH11: 1.351 | AI11: 1.316 | AJ11: 1.293 | AK11: 1.275 | AL11: 1.259 | AM11: 1.246
A12: 0.001 | B12: 2.515 | D12: -1.6 | E12: 0.8835 | J12: 0.006 | K12: 2.103 | L12: 2.411 | M12: 2.56 | N12: 2.738 | P12: 22 | Q12: 125.21 | R12: 141.83 | S12: 158.15 | T12: 174.23 | U12: 190.12 | V12: 205.85 | W12: 221.45 | X12: 252.35 | Y12: 0.7 | Z12: 1.04 | AA12: 0.86 | AB12: 0.77 | AC12: 0.7 | AD12: 0.65 | AE12: 0.58 | AG12: 0.7 | AH12: 1.338 | AI12: 1.305 | AJ12: 1.284 | AK12: 1.268 | AL12: 1.255 | AM12: 1.243
A13: 0.0011 | B13: 2.456 | D13: -1.5 | E13: 0.8612 | J13: 0.007 | K13: 2.014 | L13: 2.311 | M13: 2.459 | N13: 2.639 | P13: 24 | Q13: 128.75 | R13: 146.27 | S13: 163.47 | T13: 180.39 | U13: 197.1 | V13: 213.62 | W13: 230 | X13: 262.42 | Y13: 0.8 | Z13: 1.1 | AA13: 0.93 | AB13: 0.84 | AC13: 0.77 | AD13: 0.72 | AE13: 0.64 | AG13: 0.8 | AH13: 1.326 | AI13: 1.297 | AJ13: 1.278 | AK13: 1.265 | AL13: 1.253 | AM13: 1.242
A14: 0.0012 | B14: 2.404 | D14: -1.4 | E14: 0.8366 | J14: 0.008 | K14: 1.933 | L14: 2.228 | M14: 2.379 | N14: 2.567 | P14: 26 | Q14: 131.93 | R14: 150.32 | S14: 168.36 | T14: 186.11 | U14: 203.61 | V14: 220.91 | W14: 238.05 | X14: 271.94 | Y14: 0.9 | Z14: 1.17 | AA14: 1 | AB14: 0.92 | AC14: 0.84 | AD14: 0.79 | AE14: 0.7 | AG14: 0.9 | AH14: 1.316 | AI14: 1.288 | AJ14: 1.273 | AK14: 1.261 | AL14: 1.252 | AM14: 1.243
A15: 0.0013 | B15: 2.357 | D15: -1.3 | E15: 0.8071 | J15: 0.009 | K15: 1.861 | L15: 2.159 | M15: 2.312 | N15: 2.499 | Y15: 1 | Z15: 1.23 | AA15: 1.07 | AB15: 0.99 | AC15: 0.91 | AD15: 0.85 | AE15: 0.75 | AG15: 1 | AH15: 1.308 | AI15: 1.283 | AJ15: 1.269 | AK15: 1.26 | AL15: 1.253 | AM15: 1.244
A16: 0.0014 | B16: 2.314 | D16: -1.2 | E16: 0.7792 | J16: 0.01 | K16: 1.809 | L16: 2.108 | M16: 2.262 | N16: 2.445 | Y16: 1.1 | Z16: 1.3 | AA16: 1.14 | AB16: 1.06 | AC16: 0.98 | AD16: 0.92 | AE16: 0.81 | AG16: 1.1 | AH16: 1.301 | AI16: 1.278 | AJ16: 1.266 | AK16: 1.259 | AL16: 1.255 | AM16: 1.248
A17: 0.0015 | B17: 2.275 | D17: -1.1 | E17: 0.7485 | F17: 0.7896 | J17: 0.012 | K17: 1.722 | L17: 2.019 | M17: 2.173 | N17: 2.362 | Y17: 1.2 | Z17: 1.37 | AA17: 1.22 | AB17: 1.14 | AC17: 1.05 | AD17: 0.98 | AE17: 0.86 | AG17: 1.2 | AH17: 1.295 | AI17: 1.274 | AJ17: 1.265 | AK17: 1.261 | AL17: 1.259 | AM17: 1.252
A18: 0.0016 | B18: 2.239 | D18: -1 | E18: 0.7159 | F18: 0.7532 | J18: 0.014 | K18: 1.663 | L18: 1.959 | M18: 2.117 | N18: 2.309 | Y18: 1.3 | Z18: 1.43 | AA18: 1.29 | AB18: 1.21 | AC18: 1.13 | AD18: 1.04 | AE18: 0.91 | AG18: 1.3 | AH18: 1.29 | AI18: 1.272 | AJ18: 1.264 | AK18: 1.262 | AL18: 1.265 | AM18: 1.257
A19: 0.0017 | B19: 2.205 | D19: -0.9 | E19: 0.6818 | F19: 0.7174 | J19: 0.016 | K19: 1.614 | L19: 1.912 | M19: 2.072 | N19: 2.27 | Y19: 1.4 | Z19: 1.5 | AA19: 1.37 | AB19: 1.29 | AC19: 1.2 | AD19: 1.1 | AE19: 0.95 | AG19: 1.4 | AH19: 1.285 | AI19: 1.27 | AJ19: 1.264 | AK19: 1.267 | AL19: 1.272 | AM19: 1.265
A20: 0.0018 | B20: 2.174 | D20: -0.8 | E20: 0.6481 | F20: 0.6819 | J20: 0.018 | K20: 1.576 | L20: 1.879 | M20: 2.037 | N20: 2.24 | Y20: 1.5 | Z20: 1.58 | AA20: 1.44 | AB20: 1.36 | AC20: 1.27 | AD20: 1.16 | AE20: 1 | AG20: 1.5 | AH20: 1.282 | AI20: 1.269 | AJ20: 1.265 | AK20: 1.273 | AL20: 1.283 | AM20: 1.273
A21: 0.0019 | B21: 2.145 | D21: -0.7 | E21: 0.6143 | F21: 0.65 | J21: 0.02 | K21: 1.544 | L21: 1.849 | M21: 2.004 | N21: 2.216 | Y21: 1.6 | Z21: 1.65 | AA21: 1.52 | AB21: 1.44 | AC21: 1.34 | AD21: 1.22 | AE21: 1.05 | AG21: 1.6 | AH21: 1.279 | AI21: 1.268 | AJ21: 1.267 | AK21: 1.28 | AL21: 1.295 | AM21: 1.282
A22: 0.002 | B22: 2.119 | D22: -0.6 | E22: 0.5787 | F22: 0.618 | G22: 0.6685 | J22: 0.025 | K22: 1.493 | L22: 1.808 | M22: 1.965 | N22: 2.188 | Y22: 1.7 | Z22: 1.72 | AA22: 1.59 | AB22: 1.51 | AC22: 1.4 | AD22: 1.28 | AE22: 1.09 | AG22: 1.7 | AH22: 1.277 | AI22: 1.268 | AJ22: 1.271 | AK22: 1.289 | AL22: 1.307 | AM22: 1.29
A23: 0.0021 | B23: 2.094 | D23: -0.5 | E23: 0.5428 | F23: 0.5847 | G23: 0.6292 | J23: 0.03 | K23: 1.46 | L23: 1.788 | M23: 1.954 | N23: 2.187 | Y23: 1.8 | Z23: 1.8 | AA23: 1.67 | AB23: 1.59 | AC23: 1.47 | AD23: 1.33 | AE23: 1.13 | AG23: 1.8 | AH23: 1.274 | AI23: 1.268 | AJ23: 1.277 | AK23: 1.3 | AL23: 1.32 | AM23: 1.298
A24: 0.0022 | B24: 2.07 | D24: -0.4 | E24: 0.5092 | F24: 0.5509 | G24: 0.5953 | J24: 0.035 | K24: 1.442 | L24: 1.784 | M24: 1.963 | N24: 2.201 | Y24: 1.9 | Z24: 1.87 | AA24: 1.74 | AB24: 1.66 | AC24: 1.53 | AD24: 1.38 | AE24: 1.17 | AG24: 1.9 | AH24: 1.272 | AI24: 1.27 | AJ24: 1.284 | AK24: 1.313 | AL24: 1.334 | AM24: 1.306
A25: 0.0023 | B25: 2.047 | D25: -0.3 | E25: 0.4768 | F25: 0.5171 | G25: 0.5613 | J25: 0.4 | K25: 1.442 | L25: 1.797 | M25: 1.988 | N25: 2.231 | Y25: 2 | Z25: 1.95 | AA25: 1.82 | AB25: 1.73 | AC25: 1.59 | AD25: 1.42 | AE25: 1.21 | AG25: 2 | AH25: 1.271 | AI25: 1.272 | AJ25: 1.291 | AK25: 1.326 | AL25: 1.346 | AM25: 1.314
A26: 0.0024 | B26: 2.025 | D26: -0.2 | E26: 0.444 | F26: 0.4835 | G26: 0.5259 | J26: 0.045 | K26: 1.451 | L26: 1.821 | M26: 2.027 | N26: 2.276 | Y26: 2.1 | Z26: 2.02 | AA26: 1.89 | AB26: 1.8 | AC26: 1.64 | AD26: 1.46 | AE26: 1.24 | AG26: 2.1 | AH26: 1.271 | AI26: 1.275 | AJ26: 1.301 | AK26: 1.34 | AL26: 1.357 | AM26: 1.321
A27: 0.0025 | B27: 2.005 | D27: -0.1 | E27: 0.4111 | F27: 0.4499 | G27: 0.4901 | J27: 0.05 | K27: 1.469 | L27: 1.858 | M27: 2.085 | N27: 2.348 | Y27: 2.2 | Z27: 2.1 | AA27: 1.97 | AB27: 1.86 | AC27: 1.69 | AD27: 1.5 | AE27: 1.27 | AG27: 2.2 | AH27: 1.27 | AI27: 1.279 | AJ27: 1.311 | AK27: 1.352 | AL27: 1.368 | AM27: 1.329
A28: 0.0026 | B28: 1.986 | D28: 0 | E28: 0.3782 | F28: 0.4164 | G28: 0.4543 | H28: 0.5793 | J28: 0.06 | K28: 1.532 | L28: 1.979 | M28: 2.262 | N28: 2.526 | Y28: 2.3 | Z28: 2.18 | AA28: 2.05 | AB28: 1.92 | AC28: 1.73 | AD28: 1.53 | AE28: 1.3 | AG28: 2.3 | AH28: 1.27 | AI28: 1.284 | AJ28: 1.323 | AK28: 1.362 | AL28: 1.377 | AM28: 1.335
A29: 0.0027 | B29: 1.967 | D29: 0.1 | E29: 0.3452 | F29: 0.3839 | G29: 0.4219 | H29: 0.539 | J29: 0.07 | K29: 1.657 | L29: 2.156 | M29: 2.467 | N29: 2.753 | Y29: 2.4 | Z29: 2.25 | AA29: 2.12 | AB29: 1.97 | AC29: 1.76 | AD29: 1.56 | AE29: 1.33 | AG29: 2.4 | AH29: 1.271 | AI29: 1.292 | AJ29: 1.334 | AK29: 1.369 | AL29: 1.383 | AM29: 1.342
A30: 0.0028 | B30: 1.95 | D30: 0.2 | E30: 0.3125 | F30: 0.3518 | G30: 0.3909 | H30: 0.5017 | Y30: 2.5 | Z30: 2.33 | AA30: 2.19 | AB30: 2.02 | AC30: 1.79 | AD30: 1.59 | AE30: 1.36 | AG30: 2.5 | AH30: 1.272 | AI30: 1.299 | AJ30: 1.345 | AK30: 1.376 | AL30: 1.388 | AM30: 1.348
A31: 0.0029 | B31: 1.933 | D31: 0.3 | E31: 0.2802 | F31: 0.3187 | G31: 0.3604 | H31: 0.4643 | Y31: 2.6 | Z31: 2.4 | AA31: 2.26 | AB31: 2.06 | AC31: 1.81 | AD31: 1.6 | AE31: 1.38 | AG31: 2.6 | AH31: 1.273 | AI31: 1.308 | AJ31: 1.354 | AK31: 1.38 | AL31: 1.392 | AM31: 1.354
A32: 0.003 | B32: 1.917 | D32: 0.4 | E32: 0.2491 | F32: 0.285 | G32: 0.3303 | H32: 0.4305 | Y32: 2.7 | Z32: 2.47 | AA32: 2.33 | AB32: 2.08 | AC32: 1.82 | AD32: 1.62 | AE32: 1.41 | AG32: 2.7 | AH32: 1.276 | AI32: 1.317 | AJ32: 1.362 | AK32: 1.383 | AL32: 1.395 | AM32: 1.359
A33: 0.0031 | B33: 1.902 | D33: 0.5 | E33: 0.22 | F33: 0.2533 | G33: 0.3003 | H33: 0.3972 | Y33: 2.8 | Z33: 2.54 | AA33: 2.39 | AB33: 2.11 | AC33: 1.82 | AD33: 1.63 | AE33: 1.43 | AG33: 2.8 | AH33: 1.278 | AI33: 1.326 | AJ33: 1.368 | AK33: 1.385 | AL33: 1.397 | AM33: 1.363
A34: 0.0032 | B34: 1.887 | D34: 0.6 | E34: 0.1944 | F34: 0.2255 | G34: 0.2703 | H34: 0.3639 | Y34: 2.9 | Z34: 2.62 | AA34: 2.45 | AB34: 2.12 | AC34: 1.83 | AD34: 1.64 | AE34: 1.45 | AG34: 2.9 | AH34: 1.283 | AI34: 1.336 | AJ34: 1.372 | AK34: 1.387 | AL34: 1.398 | AM34: 1.367
A35: 0.0033 | B35: 1.873 | D35: 0.7 | E35: 0.1692 | F35: 0.1982 | G35: 0.2414 | H35: 0.3332 | Y35: 3 | Z35: 2.69 | AA35: 2.5 | AB35: 2.13 | AC35: 1.83 | AD35: 1.66 | AE35: 1.47 | AG35: 3 | AH35: 1.287 | AI35: 1.343 | AJ35: 1.376 | AK35: 1.389 | AL35: 1.399 | AM35: 1.37
A36: 0.0034 | B36: 1.86 | D36: 0.8 | E36: 0.1465 | F36: 0.1717 | G36: 0.2137 | H36: 0.3037 | Y36: 3.1 | Z36: 2.77 | AA36: 2.53 | AB36: 2.13 | AC36: 1.82 | AD36: 1.66 | AE36: 1.49 | AG36: 3.1 | AH36: 1.291 | AI36: 1.35 | AJ36: 1.379 | AK36: 1.392 | AL36: 1.4 | AM36: 1.373
A37: 0.0035 | B37: 1.847 | D37: 0.9 | E37: 0.1241 | F37: 0.1471 | G37: 0.19 | H37: 0.2763 | Y37: 3.2 | Z37: 2.85 | AA37: 2.55 | AB37: 2.13 | AC37: 1.82 | AD37: 1.66 | AE37: 1.5 | AG37: 3.2 | AH37: 1.297 | AI37: 1.355 | AJ37: 1.382 | AK37: 1.393 | AL37: 1.4 | AM37: 1.376
A38: 0.0036 | B38: 1.834 | D38: 1 | E38: 0.1057 | F38: 0.1265 | G38: 0.1675 | H38: 0.2504 | Y38: 3.3 | Z38: 2.92 | AA38: 2.56 | AB38: 2.12 | AC38: 1.81 | AD38: 1.67 | AE38: 1.52 | AG38: 3.3 | AH38: 1.303 | AI38: 1.36 | AJ38: 1.384 | AK38: 1.394 | AL38: 1.401 | AM38: 1.379
A39: 0.0037 | B39: 1.822 | D39: 1.1 | E39: 0.0873 | F39: 0.1086 | G39: 0.1465 | H39: 0.2261 | Y39: 3.4 | Z39: 2.98 | AA39: 2.56 | AB39: 2.12 | AC39: 1.8 | AD39: 1.67 | AE39: 1.54 | AG39: 3.4 | AH39: 1.309 | AI39: 1.363 | AJ39: 1.386 | AK39: 1.395 | AL39: 1.401 | AM39: 1.381
A40: 0.0038 | B40: 1.81 | D40: 1.2 | E40: 0.073 | F40: 0.0941 | G40: 0.1289 | H40: 0.2041 | Y40: 3.5 | Z40: 3.05 | AA40: 2.55 | AB40: 2.1 | AC40: 1.79 | AD40: 1.67 | AE40: 1.55 | AG40: 3.5 | AH40: 1.316 | AI40: 1.367 | AJ40: 1.388 | AK40: 1.397 | AL40: 1.401 | AM40: 1.383
...

Sheet 2.1, 기존시설(50년빈도)
A1: 추자항 파제제 축조공사
A2: 1.1 기본제원검토
A3: 1.1.1 마루높이 검토
A5: 가. 마루높이 결정
A6: 1) 검토방향
B7: ▸ 마루높이는 일반적으로 배후수역의 정온도, 배후 항만시설의 보전등을 감안
B8: 설계조위상 적정한 마루높이로 결정
A10: 2) 검토방법
B11: ▸ 마루높이는 다음의 방법을 고려하여 결정
B12: - 항만 및 어항설계기준에 의한 방법
B13: - 처오름높이에 의한 방법
B14: - 허용월파량에 의한 방법
B15: - 항내 전달파고에 의한 방법
A17: 3) 검토조건
B18: 가) 파랑조건
B19: 구 분 | L19: 파고(H⅓) | Q19: 주기(T⅓) | W19: 설계수심 | AC19: 해저경사 | AI19: 비 고
B20: 기존시설물 | H20: B | L20: 3.5 | Q20: 11.3 | W20: -10 | AC20: =1/50 -> 0.02
H21: C | L21: 4.2 | Q21: 11.3 | W21: =W20 -> -10 | AC21: =AC20 -> 0.02
H22: D | L22: 4 | Q22: 11.3 | W22: -10 | AC22: =AC21 -> 0.02
B24: 나) 조위조건
B25: 구 분 | P25: 조 위 (m) | W25: 조 위 표
B26: 약최고고조위 | I26: Aprox.H.H.W | P26: 3.356
B27: 대조평균고조위 | I27: H.W.O.S.T | P27: 2.904
B28: 평균고조위 | I28: H.W.O.M.T | P28: 2.554
B29: 소조평균고조위 | I29: H.W.O.N.T | P29: 2.204
B30: 평균해면 | I30: M.S.L | P30: 1.678
B31: 소조평균저조위 | I31: L.W.O.N.T | P31: 1.152
B32: 평균저조위 | I32: L.W.O.M.T | P32: 0.802
B33: 대조평균저조위 | I33: L.W.O.S.T | P33: 0.452
B34: 약최저저조위 | I34: Aprox.L.L.W | P34: 0

Sheet 나.마루높이검토(기존시설50년)
A1: 나. 마루높이 검토
A2: 1) 마루높이 산정방법
